Workbook

Sheet 表紙・凡例
B2: MizuniGoal Power Controller v3.0.0 試験記録シート
B3: 7S4P LiPo 2並列ホットスワップ電源基板／マイコン保護化（v2.1.1 → v3.0.0）
B5: 基板情報
B6: 基板 No. | C6: 3 号機（v3.0.0 初号基板。1 号機は 2026-10-08 に Q3 破壊、2 号機は v2.1.1 のまま試験用に保持）
B7: 基板バージョン | C7: v3.0.0
B8: 実装日
B9: 実装方法 | C9: PCBA（SMD 118 点、J7 を含む）＋ 手実装／THT（J1 / J2 / J3 / J4 / J5 / J6 / J8 の 7 点）
B10: 銅厚 | C10: 1oz
B11: 表面仕上げ | C11: ENIG
B12: ファームウェア版数
B13: 試験実施者
B14: 試験実施日
B16: 凡例
B17: 黄色セル | C17: 記入欄。ここだけ入力してください
B18: 灰色セル | C18: 自動計算。数式が入っているので編集しないでください
B19: 橙色の行 | C19: 安全上の注意または手順の順序に関する警告
B20: 判定列 | C20: OK / NG / 未実施 をドロップダウンから選択
B22: 安全上の注意・ブリングアップ手順
B23: ★【最重要・ブリングアップ】マイコンが未書込みの基板は Vout が出ません。これは故障ではなく設計どおりです。未書込みのチップは GPIO が Hi-Z のため PA5（SHDN_REQ）が浮き、R42（1MΩ）が EN_GATE を +3V3 へ引き上げて Q6（BSS138）が ON になり、EN が GND に落ちて LM5060 が遮断します。JP1 をはんだブリッジすると EN_GATE が GND に固定され Q6 が強制 OFF になるので、ファームウェアが無い状態でも電源部だけを単体で動かせます。★ 書き込み後は必ず JP1 を開放に戻してください。ブリッジしたままだとマイコンによる遮断（サーマル保護・短絡検出・非常停止のソフト側）が一切効きません。
B24: ★ 出力（Vout − GND）を短絡させないこと。1 号機はこれで Q3 のゲート酸化膜が破壊されました。電源の電流制限は無関係で、上流コンデンサの電荷（MDDS30 接続時 1.45J）が原因です。v3.0.0 では R51 / D12 を追加しましたが、MDDS30 を接続した状態での短絡はなお想定外です。MDDS30 の端子付近でプローブを扱う作業は、必ず電源を落とし放電してから行ってください。
B25: ・7S LiPo は短絡時に数百 A を供給します。フェーズ 0〜5 は可変電源（電流制限付き）で確認し、パック接続はフェーズ 7 以降にしてください。
B26: ・VB+ / VB− をドライバ等の金属で短絡しないこと。29V は感電しない電圧ですが、1.45J は工具の先端を溶着させるのに十分です。
B27: ・フェーズ 7 の 25A ストール試験では消火器を手元に置き、目を離さないこと。初回は 15A 程度から段階的に上げてください。
B28: ・R11（200Ω）の連続導通は 5.2W。実効熱抵抗 18℃/W 前後（v2.1.1 実測）では周囲 65℃ で平衡 158℃ となり最高使用温度 150℃ を超えます。試験時は 120℃ を上限に中止してください。v3.0.0 では TH2 とファームウェア #5 / #6 がこれを止める構成ですが、その保護自体を検証する試験（5-6 / 5-16）では必ず温度を監視してください。
B29: ・11-8 の LED 線短絡試験と 5-11 の出力短絡試験は意図的な短絡です。必ず電流制限付き電源で、パックと MDDS30 を外して実施してください。
B30: ・フェーズ 3 以降は、待機電流測定を除き非常停止ボタンを解除（スイッチ ON）した状態で実施してください。J4 の接点は NC で、押下中は EN 経路が開いて Vout が出ません。
B31: ・SWD デバッグ中にブレークポイントで止めると、GPIO の出力レジスタは保持されるため PA5 は Low（運転）のままで、サーマル監視ループだけが停止します。MDDS30 を外すか電流制限付き電源で行い、モータを繋いだまま長時間ブレークしないこと。
B32: ・互換 ST-LINK には 3.3V の隣に 5V が出ているものがあります。J6 を 1 ピンずらして挿すと 3.3V レールに 5V が入り IC6 が破壊されます。pin1（角パッド側・上端）の位置をシルクで必ず確認してください。J6 は v3.0.0 では PCBA で実装済みです。
B34: 試験の実施順序
B35: フェーズ | C35: シート | D35: 電源 | E35: パック | F35: 実施条件
B36: 0 | C36: 0_通電前確認 | D36: なし | E36: なし | F36: 無通電。ここで異常があれば通電しない
B37: 1 | C37: 1_3.3V電源 | D37: 可変電源 12〜35V / 0.3A 制限 | E37: なし | F37: ★ Vout は出ない状態で実施（これが正常）
B38: 2 | C38: 2_MCU書き込みと基本動作 | D38: 可変電源 24V / 0.5A 制限 | E38: なし | F38: JP1 の扱いが本フェーズの要点
B39: 3 | C39: 3_低電圧基本動作 | D39: 可変電源 0〜35V / 0.5A 制限 | E39: なし | F39: MDDS30 未接続
B40: 4 | C40: 4_起動波形 | D40: 可変電源 29.4V / ★3A 以上 | E40: なし | F40: MDDS30 接続。電流制限不足は測定を無効にする
B41: 5 | C41: 5_保護機能（マイコン） | D41: 可変電源 24V / 0.5A 制限 | E41: なし | F41: 5-10 の短絡試験は MDDS30 も外す
B42: 6 | C42: 6_Q3ゲート保護 | D42: 可変電源 29.4V / 0.5A 制限 | E42: なし | F42: 6-4 は MDDS30 を外して実施
B43: 7 | C43: 7_熱特性 / 8_ブレーキチョッパ | D43: パックまたは大容量電源 | E43: 接続 | F43: 実走行。消火器を手元に
B44: 8 | C44: 9_走行時総合 / 10_GND分離 / 11_外部スイッチ・LED | D44: パック | E44: 接続 | F44: 実走行。11-7 のみ電流制限付き電源
B45: — | C45: 12_量産工程 / 13_量産記録 | D45: 可変電源 24V / 0.2A 制限 | E45: なし | F45: ★試作では使わない。300 枚ロットの量産工程（全数 P-1〜P-7 ＋ 抜取り）
...

Sheet 0_通電前確認
A1: 0_通電前確認
A2: 通電前に必ず実施。ここで異常があれば通電しないこと。0-2 / 0-6 / 0-7 / 0-10〜0-16 / 0-22〜0-24 は v3.0.0 で追加した項目です。
A4: No. | B4: 項目 | C4: 手順・条件 | D4: 測定点 | E4: 設計値・判定基準 | F4: 単位 | G4: 実測値 | H4: 判定 | I4: 備考
A5: 0-1 | B5: 目視確認 | C5: ルーペで全部品を確認 | D5: 基板全体 | E5: ブリッジ・未はんだ・欠品・向き違いが無いこと。特に IC6（TSSOP-20、0.65mm ピッチ）と IC4（SOT-23-6） | F5: —
A6: 0-2 | B6: JP1 の状態 | C6: 基板を目視。はんだブリッジの有無を見る | D6: JP1 | E6: ★ 初回は「開放」であることを確認。未書込みのまま通電すると Vout は出ないが、それが正しい状態（2-4 で確認する） | F6: —
A7: 0-3 | B7: 短絡確認 | C7: DMM の抵抗レンジ | D7: J1 の +/− 間 | E7: 数百Ω以上。C5 / C7 の充電で表示が上昇し続けること（数Ωで止まる場合は短絡） | F7: Ω
A8: 0-4 | B8: 短絡確認 | C8: 同上 | D8: J2 の +/− 間 | E8: 同上 | F8: Ω
A9: 0-5 | B9: 短絡確認 | C9: 同上 | D9: J3 の +/− 間 | E9: 同上 | F9: Ω
A10: 0-6 | B10: 3.3V レールの短絡確認 | C10: DMM の抵抗レンジ（無通電） | D10: TP24 − TP32 | E10: 数 kΩ 以上で、C30 / C24 / C25 の充電により上昇し続けること。数Ω で止まる場合は IC4 / IC6 / C30 のいずれかが短絡している | F10: Ω
A11: 0-7 | B11: 3.3V と VBUS の分離 | C11: 同上 | D11: TP24 − TP4 | E11: OL または非常に高い値。導通していたら IC4 の実装不良 | F11: —
A12: 0-8 | B12: 導通確認 | C12: DMM のダイオードレンジ | D12: TP10 → TP4 | E12: Q3 ボディダイオード方向で導通（約 0.5V） | F12: V
A13: 0-9 | B13: ビア確認 | C13: 基板を透かして裏面を確認 | D13: Q1/Q2/Q3 裏面 | E13: はんだの染み出しが無いこと（テンティング成立） | F13: —
A14: 0-10 | B14: R51 の実装・値 | C14: DMM の抵抗レンジ（無通電） | D14: TP5 − IC3.10（GATE ピン） | E14: 100Ω ±5%。ここが開放だと Q3 のゲートが駆動されない | F14: Ω
A15: 0-11 | B15: D12 の向き | C15: DMM のダイオードレンジ | D15: TP5 − TP10 | E15: TP5 側が＋で OL（TVS の阻止方向）、逆向きで約 0.6〜0.9V の順方向。逆なら実装の向きが誤り | F15: V
A16: 0-12 | B16: D11 の向き | C16: 同上 | D16: R39.1（D11 カソード）− TP24 | E16: TP24 側が＋で約 0.3V（順方向）、逆で OL。BAT46W のアノードが +3V3 側 | F16: V
... A35: 0-31 | B35: F4 の導通 | C35: DMM の抵抗レンジ（無通電） | D35: TP4 − J8 pin2 | E35: 数Ω 以下（AEM F1206HI2000V063TM、2A / 63V 高インラッシュ）。開放なら VBUS_AUX が出ない | F35: Ω
A37: ※ 0-6 / 0-7 は v3.0.0 で追加した項目です。3.3V レールが短絡したまま通電すると IC4 が過熱します。 ※ 0-25〜0-31 は 2026-10-21 に追加した項目です。2026-10-14 以降の設計変更（R54 / R70 / R73 / R74 / R75 / C64 / C69 / U3 / IC5 / J5 / J7 / J8 / F4）に対応します。
A38: ※ 0-10 / 0-11 は 2026-10-08 の Q3 破壊を受けて追加した R51 / D12 の実装確認です。どちらか一方でも欠けると、出力短絡時に Q3 のゲート酸化膜が再び破壊されます。
A39: ※ 0-13〜0-16 は EN フェイルセーフ経路の確認です。R42 が欠けると未書込み時に EN_GATE が浮いて遮断が不定になり、R40 が欠けると J4 断線時に EN が落ちません。
A40: ※ 0-18 / 0-19 は v2.0.0 で R20 の接続先を誤っていた箇所です。R20 の上端が 12V レールではなく分圧ノードに繋がっていたため、TL431 にバイアス電流が流れず VREF が立ちませんでした。
A41: ※ 抵抗レンジでの測定は、どの項目も「表示が安定してから読む」か「上昇し続けることを確認する」のどちらかです。0-3〜0-6 は上昇し続けることが正常、0-10 / 0-13〜0-15 / 0-18 / 0-20 / 0-23 は安定後の値が判定対象です。
A42: ※ 測定前に C5 / C7 を放電させてください。前の測定で充電が残っていると高い値が表示され、短絡を見逃します。

Sheet 1_3.3V電源
A1: 1_3.3V電源（IC4 / LMR16006XDDCR）
A2: 可変電源を電流制限 0.3A に設定し、J1 に接続して実施。パックと MDDS30 は接続しない。★ このフェーズでは Vout は出ません（未書込みのフェイルセーフ動作で、正常です）。
A4: No. | B4: 項目 | C4: 手順・条件 | D4: 測定点 | E4: 設計値・判定基準 | F4: 単位 | G4: 実測値 | H4: 判定 | I4: 備考
A5: 1-1 | B5: 3.3V の立ち上がり | C5: VBUS 12V、電流制限 0.3A。J4 は開放（非常停止を押した状態） | D5: TP24 − TP32 | E5: 3.307V ±3%（3.21〜3.41V）。R44 100kΩ / R45 30.1kΩ で 0.765 × (1 + 100/30.1) | F5: V
A6: 1-2 | B6: VBUS 依存性 | C6: VBUS を 12 / 19.5 / 24 / 29.4 / 35V と変えて TP24 を読む | D6: TP24 − TP32 | E6: 全点で ±1% 以内（3.27〜3.34V）。変動するなら FB 分圧か IC4 の実装を疑う | F6: V
A7: 1-3 | B7: 出力リプル | C7: VBUS 29.4V、AC カップリング、20MHz 帯域制限、グランドスプリング使用 | D7: TP24 − TP32 | E7: 設計 1.0mV（ΔIL 127mA / C30 22µF）。スイッチングスパイクを含め 30mVpp 以下 | F7: mVpp
A8: 1-4 | B8: スイッチング周波数 | C8: L2 の IC4 側端子（SW_3V3）を観測。10× プローブ | D8: L2.1 − TP32 | E8: 0.7MHz ±15%（595〜805kHz）。X 版（0.7MHz）であることの確認 | F8: kHz
A9: 1-5 | B9: デューティ | C9: VBUS 29.4V、同時観測 | D9: L2.1 − TP32 | E9: 11.25% 前後（3.307 ÷ 29.4）。ON 時間 161ns は規格最小 80ns の 2 倍 | F9: %
A10: 1-6 | B10: SW ノードのリンギング | C10: VBUS 35V、SW 立ち上がりのピークを読む | D10: L2.1 − TP32 | E10: 60V（IC4 の SW 絶対最大）を超えないこと。超える場合は C27 / D10 のループが大きい | F10: V
A11: 1-7 | B11: SW ノードのループ確認 | C11: 1-6 と同時。サーマルカメラまたは目視でも可 | D11: C27 / D10 / IC4 | E11: リンギングの周波数が 100MHz を大きく超えない。C27 → IC4.5 → IC4.6 → D10 → C27 が数 mm に収まっていること | F11: MHz
A12: 1-8 | B12: 3.3V 負荷電流（遮断時） | C12: VBUS 29.4V、非常停止を解除（J4 接点 ON）、マイコン未書込みまたは PA5 = H | D12: 電源の電流表示から換算、または L2 に直列で測定 | E12: 約 15.9mA。内訳は EN チェーン 13mA（2.95V ÷ 220Ω、Q6 が ON で EN を 78mV に引くため）＋ MCU 等 1mA ＋ U3 INA240A2PW 1.8mA ＋ IC5 TLV9001 60µA。★ 2026-10-14 以降に U3 / IC5 を追加したため +1.9mA | F12: mA
A13: 1-9 | B13: 3.3V 負荷電流（運転時） | C13: VBUS 29.4V、マイコン書込み済みで PA5 = L | D13: 同上 | E13: 約 8.0mA。MCU 2mA ＋ LED3 2.8mA ＋ EN ループ 1.22mA ＋ U3 INA240A2PW 1.8mA ＋ IC5 TLV9001 60µA。0.6A 定格に対し十分 | F13: mA
A14: 1-10 | B14: 3.3V 負荷電流（待機時） | C14: VBUS 29.4V、非常停止を押した状態（J4 開放）、MCU は STOP | D14: 同上 | E14: 約 1.9mA（U3 INA240A2PW 1.8mA typ ＋ IC5 TLV9001 60µA）。2.5mA 以下。★ U3 / IC5 は +3V3 に常時接続で J4 / PA5 では切れない。J4 が開くと EN チェーンの 13mA のみが消える | F14: mA
A15: 1-11 | B15: IC4 の温度 | C15: 1-8 の状態を 10 分継続 | D15: IC4 パッケージ | E15: 周囲＋10℃ 以内。15.9mA × 3.3V ÷ 効率 80% − 出力 = 約 13mW の損失 | F15: ℃
A16: 1-12 | B16: L2 の温度 | C16: 同上 | D16: L2 | E16: 周囲＋5℃ 以内 | F16: ℃
A18: ★ このフェーズでは Vout は出ません。3.3V レールは IC4 が VBUS（Q3 の前）から直接作っているため、Q3 が遮断されていても 3.3V は立ちます。Vout が出ないのは未書込み（または PA5 = H）によるフェイルセーフ動作で、正常です。
A19: ※ 1-8 の 13mA は設計仕様書に記載のない値です。EN_SRC 2.95V が R39 220Ω と Q6（Rds 約 6Ω）を通って GND に流れるため、遮断状態のほうが運転状態より 3.3V 負荷が重くなります。IC4 の 0.6A 定格に対しては問題ありませんが、長時間この状態で放置すると無駄に電力を消費します。待機させるときは非常停止を押して J4 を開放してください（1-10）。
A20: ※ 1-3 のリプルはグランドスプリングを使わないと測れません。10cm のグランドリードでは 0.7MHz のスイッチングノイズを拾って実際の 10 倍以上に見えます。
A21: ※ 1-6 で 60V を超える場合は、C27（2.2µF / 100V / 1210）と D10（SS210）の配置を見直してください。このループが IC4 周辺で最もノイズが大きい経路です。
A22: ※ IC4 の VIN 絶対最大は 65V、SW は 65V です。7S 満充電 29.4V に対し十分な余裕がありますが、1-6 のリンギング次第では SW が危険域に入ります。

Sheet 2_MCU書き込みと基本動作
A1: 2_MCU 書き込みと基本動作（IC6 / STM32C011F4P6）
A2: 可変電源 24V・電流制限 0.5A。JP1 の扱いが本フェーズの要点です。2-4 → 2-5 → 2-6 の順を守ってください。
A4: No. | B4: 項目 | C4: 手順・条件 | D4: 測定点 | E4: 設計値・判定基準 | F4: 単位 | G4: 実測値 | H4: 判定 | I4: 備考
A5: 2-1 | B5: J6 の実装確認 | C5: PCBA で実装済み。ルーペで目視 | D5: J6 | E5: 5 本すべてはんだ付けされ、角パッド側（上端）が pin1 = +3V3 であることをシルクで確認する。★ 1 ピンずれて挿すと 3.3V レールに 5V が入り IC6 が壊れるので、ケーブルを挿す前に必ず向きを確認 | F5: —
A6: 2-2 | B6: ST-LINK の給電方式判定 | C6: ST-LINK を PC に挿し、基板に何も繋がない状態で VDD_TARGET 相当のピンと GND 間を測る | D6: ST-LINK 側 | E6: 3.3V = 出力型（互換品に多い）／0V = 入力型（純正）。★ 出力型の場合は 4 線ケーブル（SWDIO / SWCLK / NRST / GND）を使い、3.3V は繋がない | F6: V
A7: 2-3 | B7: SWD の認識 | C7: VBUS 24V を投入し、ST-LINK で接続（4 線） | D7: J6 | E7: ST-LINK Utility / CubeProgrammer が STM32C011 を認識すること | F7: —
A8: 2-4 | B8: ★ 未書込み状態の確認 | C8: VBUS 24V、JP1 開放、非常停止を解除。書き込み前に測る | D8: TP25 / TP7 / TP10 | E8: TP25（EN_GATE）＝ 3.3V、TP7（EN）＜ 0.1V、TP10（Vout）＝ 0V。★ Vout が出ないのが正常。R42 1MΩ が EN_GATE を引き上げ Q6 が ON になっている | F8: V
A9: 2-5 | B9: JP1 ブリッジ時の動作 | C9: JP1 をはんだブリッジし、VBUS 24V を再投入 | D9: TP25 / TP7 / TP10 | E9: TP25 ＝ 0V、TP7 ＝ 2.68V、TP10 ＝ Vout が立ち上がる。ファームウェア無しで電源部だけを動かせる状態 | F9: V
A10: 2-6 | B10: ★ JP1 の開放 | C10: 電源を落とし、JP1 のはんだブリッジを除去する | D10: JP1 | E10: 開放に戻したことを導通で確認（pad1 − pad2 が OL）。★ ブリッジしたままだとマイコンの遮断が一切効かない | F10: —
A11: 2-7 | B11: 書き込み | C11: ファームウェアを書き込み、リセットする | D11: J6 | E11: 書き込みとベリファイが成功すること | F11: —
A12: 2-8 | B12: リセット直後の初期状態 | C12: リセット後 10ms 以内を観測（Ch1 = TP28、Ch2 = TP10） | D12: TP28 / TP25 / TP10 | E12: TP28（SHDN_REQ）＝ 3.3V、TP25 ＝ 3.3V、Vout ＝ 0V。ファームウェア #1 の「PA5 = H で開始」 | F12: V
A13: 2-9 | B13: 運転への移行 | C13: ADC 校正とセンサ読みが終わるまでの時間を測る | D13: TP28 / TP10 | E13: TP28 が Low に落ち、続いて Vout が立ち上がる。リセットから数十 ms 以内 | F13: ms
A14: 2-10 | B14: 運転時の EN 系電位 | C14: VBUS 29.4V、運転中 | D14: TP28 / TP25 / TP7 | E14: TP28 ＝ 0V、TP25 ＜ 0.1V、TP7 ＝ 2.68V（設計値） | F14: V
A15: 2-11 | B15: EN_SRC 電圧 | C15: 同上 | D15: D11 カソード（R39.1）− TP32 | E15: 2.95V（3.3V − BAT46W の VF 0.35V） | F15: V
A16: 2-12 | B16: NTC 駆動のデューティ | C16: TP27 を 10ms/div で観測 | D16: TP27 − TP32 | E16: 50ms 周期で 0.5ms 幅の H パルス（デューティ約 1%）。ファームウェア #2 | F16: ms
... A26: 2-22 | B26: STOP からの復帰 | C26: 非常停止を解除する | D26: TP10 / TP26 | E26: EN が即座に立ち上がって Vout が出る。同時に EXTI で MCU が復帰し、数 ms 以内に TH1 を読むこと | F26: ms
A28: ★ 2-4 → 2-5 → 2-6 の順を必ず守ってください。2-4 で「Vout が出ない」ことを確認しないまま 2-5 で JP1 をブリッジすると、フェイルセーフが働いているのか電源部が壊れているのかが切り分けられなくなります。また 2-6 で JP1 を開放に戻し忘れると、以降のフェーズ 5（保護機能）はすべて無意味になります。
A29: ※ JP1 は Jumper:SolderJumper-2_P1.3mm_Open_Pad1.0x1.5mm の基板パターンで、部品は実装しません（BOM にも載せません）。pad1 = GND、pad2 = EN_GATE です。
A30: ※ 2-5 で Vout が出ない場合、原因は JP1 より下流（IC3 / Q3 / UVLO）にあります。TP7 が 2.68V まで上がっているかで切り分けてください。TP7 が上がっていて Vout が出ないなら IC3 以降、TP7 が上がらないなら EN チェーン（D11 / R39 / J4 / R40）です。
A31: ※ 2-13 / 2-14 は PA7（NTC_DRV）が H の 0.5ms の間しか有効な電圧が出ません。DMM で測ると平均値（約 27mV）が読めるだけです。オシロのカーソルか、SWD で ADC の生値を読んでください。
A32: ※ 2-18 の 50µs は v2.1.1 の非常停止応答 266µs（ハードウェア経路）より速い値です。どちらも設計どおりで、ソフト経由のほうが C20 が小さく見えるぶん速くなります。
A33: ※ 2-19 の 93ms は「マイコンが死んでも 93ms で自動遮断される」という設計の核です。ここが測れないと故障モード表の「マイコン未書込み／死亡 → 安全」が検証できません。
A34: ※ 2-20 と 2-19 は同じ回路の両面です。2ms のリセットでは切れず（走行継続）、恒久的な死亡では 93ms で切れる。C20 100nF がこの境目を決めています。
A35: ※ デバッグビルドでは IWDG をフリーズ（DBGMCU_APB_FZR1 の DBG_IWDG_STOP）し、ファームウェア #11（IWDG リセット 3 回でラッチ）を無効化してください。有効のままだとブレークのたびに誤発火します。

Sheet 3_低電圧基本動作
A1: 3_低電圧基本動作
A2: 可変電源を電流制限 0.5A に設定し、J1 に接続して実施。パックと MDDS30 はまだ接続しない。マイコンは書込み済み・JP1 開放の状態で行うこと。3-10 を除き、非常停止ボタンは解除（スイッチ ON）の状態で実施。
A4: No. | B4: 項目 | C4: 手順・条件 | D4: 測定点 | E4: 設計値・判定基準 | F4: 単位 | G4: 実測値 | H4: 判定 | I4: 備考
A5: 3-1 | B5: UVLO 遮断→復帰 | C5: 電源電圧を 0V から徐々に上げる（非常停止は解除状態） | D5: TP10 / TP19 | E5: 19.5V 付近で Q3 が ON | F5: V
A6: 3-2 | B6: UVLO ヒステリシス | C6: 電圧を徐々に下げる（同上） | D6: TP10 / TP19 | E6: 17.4V 付近で OFF（v2.1.1 実測 17.95V） | F6: V
A7: 3-3 | B7: OVP 遮断 | C7: 電圧を 35V まで上げる（同上） | D7: TP10 / TP19 | E7: 34.0V 付近で OFF。★ 32.2V でチョッパが導通して R11 が 5.2W を食うので速やかに通過させる | F7: V
A8: 3-4 | B8: OVP 復帰 | C8: 電圧を下げる（同上） | D8: TP10 / TP19 | E8: 30.1V 付近で復帰 | F8: V
A9: 3-5 | B9: 非常停止スイッチ | C9: ボタンを押す／ひねって解除 | D9: TP10 / TP19 | E9: 押すと OFF、解除で ON（NC 接点） | F9: —
A10: 3-6 | B10: 非常停止の応答時間 | C10: 押した瞬間を観測（Ch1 = TP7、Ch2 = TP10） | D10: TP7 / TP2 | E10: TP7 が 0.8V を切るまで約 266µs（τ = R40 2.2kΩ × C12 100nF = 220µs、2.68V → 0.8V） | F10: µs
A11: 3-7 | B11: EN 電圧（運転時） | C11: 25℃、バス 29.4V、非常停止解除 | D11: TP7 / TP2 | E11: 2.68V。★ v2.1.1 の 3.9V（D8 クランプ）から変わった。3.3V 系ロジックになったため | F11: V
A12: 3-8 | B12: EN 電圧（Q6 ON 時） | C12: PA5 = H またはマイコン未書込み | D12: TP7 / TP2 | E12: 78mV（2.95V × 6Ω ÷ 226Ω）。ENTHL 0.8V を十分下回る | F12: mV
A13: 3-9 | B13: LED1 点灯 | C13: Q3 が ON の状態（同上） | D13: LED1（基板上） | E13: 点灯すること（NPGD が Low） | F13: —
A14: 3-10 | B14: 待機電流 | C14: 非常停止ボタンを押した状態、バス 29.4V、MCU は STOP | D14: 電源の電流表示 | E14: 約 460µA（暫定）。★ v2.1.1 の 60µA から増加。v3.0.0 設計値 203µA に、U3 INA240A2PW 1.8mA ＋ IC5 TLV9001 60µA を IC4（効率 80%）経由で VBUS 29.4V 側に換算した 261µA を加算。内訳は 1-8〜1-10 を参照 | F14: µA
A15: 3-11 | B15: VBUS センス分圧の確認 | C15: VBUS 29.4V | D15: TP4 / IC6.8 | E15: IC6.8 ＝ TP4 ÷ 11 ＝ 2.673V。R32 1MΩ / R33 100kΩ | F15: V
A17: ※ 3-1〜3-4 が設計値と大きくずれる場合、R2 / R3 / R4 の実装と値を確認してください。これらは v2.1.1 から変更していません。
A18: ※ 3-7 は v2.1.1 からの最大の変更点です。v2.1.1 の EN は VBUS からの分圧で D8（BZT52C3V9）が 3.9V にクランプしていました。v3.0.0 は +3V3 → D11 → R39 220Ω → J4 → R40 2.2kΩ の 3.3V 系ロジックで、D8 は ESD 保護に役割が変わっています。
A19: ※ 3-8 は 1-8 と同じ状態の別の見方です。TP7 が 78mV のとき EN チェーンには 13mA が流れています。
A20: ※ 3-10：外部 LED は Vout から駆動されるため、遮断時は消灯し待機電流に加算されません。
A21: ※ J4 の接点は NC（ノーマルクローズ）です。非常停止ボタンが押された状態では EN 経路が開いており、Vout は出ません。3-1〜3-9 は必ずボタンを解除してから実施してください。
A22: ※ J4 にスイッチを接続せずに試験する場合は、pin3 − pin4 間を短絡して接点 ON を模擬してください。開放のままでは Vout が立ち上がりません。
A23: ※ v2.1.1 の 9_ENしきい値選別（EN しきい値による遮断点の選別試験）は v3.0.0 では不要になりました。遮断点が LM5060 の EN しきい値ばらつき（0.80〜2.00V）ではなくファームウェアの定数で決まるためです。EN は 2.68V と 78mV の 2 値だけを取り、どちらも ENTHH 2.00V / ENTHL 0.80V から十分離れています。

Sheet 4_起動波形
A1: 4_起動波形
A2: MDDS30 を接続して実施。★電源の電流制限は 3A 以上に設定すること（突入 2A）。不足すると UVLO リトライで階段状の波形になり、測定が無効になる。
A4: No. | B4: 項目 | C4: 手順・条件 | D4: 測定点 | E4: 設計値・判定基準 | F4: 単位 | G4: 実測値 | H4: 判定 | I4: 備考
A5: 4-1 | B5: MDDS30 入力容量 | C5: 電源を切り放電した状態で VB+/VB− 間を 100Hz で測定 | D5: MDDS30 | E5: 参考値。v2.1.1 実測 3580〜3628µF | F5: µF
A6: 4-2 | B6: ゲート立ち上がり | C6: 非常停止を解除、Ch1 = TP5（GND:TP18）。10× プローブ、レンジは VBUS＋15V 以上 | D6: TP5 / TP18 | E6: 終値 VBUS＋12V（10〜14V）。★ TP5 は R51 の Q3 側なので、ここが真の Q3 ゲート電位。R51 の DC 降下は 24µA × 100Ω = 2.4mV で無視できる | F6: V
A7: 4-3 | B7: Vgs 終値（判定） | C7: 4-2 と同時。Ch1 = TP5、Ch2 = TP10 の差 | D7: TP5 − TP10 | E7: 10〜14V（typ 12V）。1 号機 11.8V / 2 号機 12.0V | F7: V
A8: 4-4 | B8: Vout 立ち上がり | C8: 同時観測、Ch2 = TP10（GND:TP19） | D8: TP10 / TP19 | E8: VBUS 29.4V で 42〜87ms（I_gate 17〜31µA、C_gate 44〜50nF）。typ は 57.2ms = 46.7nF × 29.4V ÷ 24µA。★ 旧 typ 53.9ms は C9+C15 の 44nF のみで計算しており、Q3 の Ciss 2.7nF を含んでいなかった | F8: ms
A9: 4-5 | B9: 突入電流 | C9: 4-4 の傾きから算出（推奨）。I = C_total × dV/dt | D9: 入力配線 | E9: 1.98A（1.4〜2.6A）、上限 2.4A。C_total = MDDS30 3628µF ＋ C7 47µF ＋ C11 1µF | F9: A
A10: 4-6 | B10: TIMER 波形 | C10: 起動時の TIMER ピン電圧。時間軸 100ms/div（1 秒窓）で 2 本目のランプまで撮る | D10: TP6 / TP2 | E10: ピークが 2.0V（ラッチ電圧）に達しないこと。★ ランプの傾きも読むこと：12.5mV/ms 前後なら I_TIMERL 6µA（正常、ラッチまで 160ms）、23mV/ms 前後なら I_TIMERH 11µA に入っており余裕が 87ms に落ちる | F10: V
A11: 4-7 | B11: TP5 − TP2 間容量 | C11: 電源を切り MDDS30 を放電した状態で DMM の容量レンジまたは LCR で測る | D11: TP5 − TP2 | E11: 約 46.7nF（C9 22nF ＋ C15 22nF ＋ Q3 の Ciss 2.7nF typ）。60〜65nF なら C9 / C15 が設計より大きい | F11: nF
A12: 4-8 | B12: 起動の単調性 | C12: 4-2 / 4-4 の波形を目視 | D12: TP5 / TP10 | E12: 階段状・ハンチングが無いこと。出る場合は電源の電流制限不足（3A 以上に設定） | F12: —
A14: ★ 電源の電流制限は 3A 以上に設定すること（突入 2A、29.4V × 2A = 59W が瞬間的に必要）。不足すると UVLO リトライで階段状の波形になり測定が無効になります。2026-10-08 午前の測定はこれで無効になりました。
A15: ※ v3.0.0 では R51 が IC3.GATE と Q3 のゲートの間に入ったため、TP5 の意味が変わりました。TP5 は /Gate_HV_1（Q3 のゲート、R51 の下流）で、C9 / C15 は Net-(IC3-GATE)（R51 の上流）側にあります。つまり TP5 − TP10 が真の Vgs で、v2.1.1 より測定点として適切になっています。
A16: ※ 4-7 の容量測定は R51 を挟んでいますが、DMM / LCR の測定周波数（概ね 100Hz〜1kHz）では 44nF のインピーダンスが 3.6kΩ 以上あり、R51 100Ω は無視できます。したがって約 46.7nF が読めます（v2.1.1 の CSD18540Q5B 時代は約 48.4nF）。
A17: ※ ゲート波形は 3 段階になります。(1) 0→約3V で Q3 がオン開始 (2) ミラー期間：Vgs が 3〜4V で平らなまま、GND 基準の TP5 は Vout と一緒に上昇（ここが t_rise） (3) Vout が VBUS に達した後、さらに 12V 分だけ上がって VBUS＋12V で停止。
A18: ※ 立ち上がり時間はゲート容量とゲート電流だけで決まり、負荷容量には依存しません。負荷容量が効くのは突入電流です。
A19: ※ 試行の間に MDDS30 の VB+ / VB− を 1kΩ / 3W で 15 秒（100Ω / 5W なら 2 秒）放電し、DMM で 0.5V 以下を確認してから次の測定に移ってください。残留電荷があると立ち上がり時間が短く出ます。★ DMM の電流レンジで放電しないこと（1.45J でヒューズが飛びます）。
A20: ★ Q1〜Q3 を BSC028N06NS に変更したことで Vgs(th) が 1.9V から 2.8V typ / 3.3V max に上がりました。起動中のミラープラトー電圧はおおよそ Vgs(th) で決まるため、最悪 3.6〜4.0V 程度まで上がります。LM5060 の TIMER 充電電流は VGS < 5V で I_TIMERL 6µA、VGS > 5V で I_TIMERH 11µA に切り替わるので、5V までの余裕が 3V から約 1V に減りました。まだ 6µA 側のはずですが、4-6 でランプの傾きを必ず読んでください。11µA に入っているとラッチまでが 160ms → 87ms に落ち、最悪条件の立ち上がり 82ms に対する余裕が 1.95 倍から 1.06 倍になります。その場合の対処は C9 / C15 の減量です（C16 の増量は短絡時の遮断を遅くするため不可）。
A21: ※ 2 号機（v2.1.1）の実測では Vout 立ち上がり 102ms で許容上限 87ms を 17% 超過しました。逆算ゲート電流 12.7µA は規格下限 17µA を下回り、原因は (a) C9＋C15 が設計の 44nF より大きい (b) IC3 の個体差 のいずれかです。v3.0.0 基板では 4-7 で先に容量を測っておくと切り分けが速くなります。
A22: ※ TIMER 容量は 0.48µF 据え置きです（設計仕様書 5_定数と根拠）。0.66µF に増やすと起動余裕は 1.31 → 1.81 倍になりますが、短絡時の遮断が 106 → 145ms に悪化するため不採用としました。短絡の高速検出はファームウェア #13（2ms）と R51 / D12 が担います。

Sheet 5_保護機能（マイコン）
A1: 5_保護機能（マイコン）
A2: 判定は温度そのもので行う。v2.1.1 では EN 電圧で判定していたが、v3.0.0 は遮断点がファームウェアの定数で決まるため温度が直接の判定基準になる。可変電源 24V・電流制限 0.5A、パックは接続しない。
A4: No. | B4: 項目 | C4: 手順・条件 | D4: 測定点 | E4: 設計値・判定基準 | F4: 単位 | G4: 実測値 | H4: 判定 | I4: 備考
A5: 5-1 | B5: T_trip 遮断（TH1） | C5: ヒートガンで TH1 を加熱。VBUS 24V、電流制限 0.5A | D5: TP28 / TP25 / TP10 | E5: TP28 が H になり Vout が落ちること。ファームウェア #3（T_trip 3 回連続） | F5: —
A6: 5-2 | B6: 遮断時の TH1 温度 | C6: 5-1 の遮断直後に加熱をやめ、TH1 の抵抗を測って温度換算する | D6: TH1 の両端 | E6: 暫定 T_trip = 95℃（NTC 809Ω）。±3℃ 以内。★ 判定は温度で行う（v2.1.1 は EN 電圧だった） | F6: ℃
A7: 5-3 | B7: 10 秒ラッチ | C7: 5-1 の後、すぐに冷却しても復帰しないことを確認 | D7: TP10 | E7: 10 秒間は Vout が戻らないこと | F7: 秒
A8: 5-4 | B8: 自動復帰 | C8: T_trip − 15℃（暫定 80℃）まで冷却する | D8: TP10 / TH1 | E8: Vout が戻ること。復帰時の TH1 温度を記録 | F8: ℃
A9: 5-5 | B9: T_hard 即時遮断 | C9: TH1 を急速に加熱して T_hard を超えさせる | D9: TP28 / TP10 | E9: 判定遅延なしで遮断されること。ファームウェア #4。暫定 T_hard = 115℃ | F9: ℃
A10: 5-6 | B10: TH2 遮断 | C10: R11 近傍（TH2）をヒートガンで加熱。R11 自体は加熱しない | D10: TP28 / TP10 / TH2 | E10: 110℃ で遮断（暫定）。ファームウェア #5。★ TH2 は NCP21X で動作上限 125℃、超えないよう監視 | F10: ℃
A11: 5-7 | B11: センサ断線検出 | C11: TH1 のパッドの片側を一時的に浮かせる（または TH1 を外す） | D11: TP28 / TP10 | E11: ADC が 3.3V 側に振れ、5 回連続でラッチ遮断。ファームウェア #7 | F11: —
A12: 5-8 | B12: センサ短絡検出 | C12: TH1 の両端を短絡する | D12: TP28 / TP10 | E12: ADC が 0V 側に振れ、5 回連続でラッチ遮断。ファームウェア #7 | F12: —
A13: 5-9 | B13: ラッチの解除 | C13: 5-7 / 5-8 の後、センサを戻して非常停止を押し→解除する | D13: TP10 | E13: J4 の再投入でラッチが解除され Vout が戻ること | F13: —
A14: 5-10 | B14: 起動失敗の検出（#8） | C14: PA5 = L の状態で Q3 のゲート駆動を阻害する（IC3.GATE を一時的に GND へ 10kΩ で引く等） | D14: TP28 / TP10 | E14: 100ms 後に Vout < 0.8 × VBUS を検出してラッチ。ファームウェア #8 | F14: ms
A15: 5-11 | B15: 出力短絡の高速検出（#13） | C15: ★ MDDS30 とパックを外し、電流制限 0.5A の可変電源で VBUS 24V。Vout − GND を 10Ω / 5W 程度の抵抗で短絡する | D15: TP28 / TP10 | E15: 2ms（1kHz × 2 回）で遮断しラッチすること。ファームウェア #13。★ 直接短絡はしない | F15: ms
A16: 5-12 | B16: #13 の armed 条件 | C16: 起動直後（Vout が 0.9 × VBUS に達する前）に 5-11 を行う | D16: TP10 | E16: 立ち上がり中は誤発火しないこと。Vout ≥ 0.9 × VBUS を一度満たすまで armed にしない仕様 | F16: —
... A20: 5-16 | B20: チョッパ ON 積算（#6） | C20: 8_ブレーキチョッパ の 8-7 の状態を維持し、積算が閾値を超えるまで待つ | D20: TP28 / TP10 / R11 | E20: 閾値超過で遮断すること。★ R11 のフランジ温度が 120℃ を超えたら即中止 | F20: 秒
A22: ★ JP1 が開放であることを確認してから本フェーズに入ってください。ブリッジされていると EN_GATE が GND に固定され、5-1〜5-16 のすべてが「遮断しない」結果になります（0-2 / 2-6）。
A23: ★ 5-11 は意図的な短絡試験です。MDDS30 とパックを必ず外し、電流制限 0.5A の可変電源で、10Ω 程度の抵抗を介して短絡してください。直接短絡（0Ω）は基板側 48µF（C7 + C11）の放電で Q3 に数百 A が流れ、R51 / D12 があっても想定外です。
A24: ※ v2.1.1 との最大の違いは判定基準です。v2.1.1 は「EN 電圧で判定し、温度は参考値」でした（LM5060 の EN しきい値が個体ごとに 0.80〜2.00V ばらつくため）。v3.0.0 は遮断点がファームウェアの定数で決まるので、温度そのものが判定基準になります。精度は NTC の J ランク ±5% と抵抗の 1% だけで決まり、±2〜3℃ です。
A25: ※ 5-2 / 5-4 / 5-5 / 5-6 の温度は、NTC の抵抗値から換算してください。サーマルカメラは放射率と熱勾配で大きく外れます（v2.1.1 では真値 82℃ に対し 120℃ と表示されました）。換算式：T = 1 / (1/298.15 + ln(R/10000)/3944) − 273.15。
A26: ※ 5-6 の TH2 は R11 から 5mm 程度離して配置しています（0-24）。R11 自体は 150℃ 以上になり得ますが、TH2 の位置では 110℃ で遮断がかかる設計です。TH2 の遮断点 110℃ は暫定値で、7-9〜7-11 の実測で確定します。
A27: ※ 5-14 / 5-15 はデバッグビルドでは #11 を無効にしている可能性があります。本試験ではリリースビルドで実施してください。
A28: ※ 5-16 の閾値（直近 10 秒のチョッパ ON 積算）は未確定です。9-6 / 9-7 の回生プロファイル実測で決めます。本項目はその後に実施してください。
A29: ※ 故障モード表（設計仕様書 8_故障モード）のうち、Q6 のオープン故障は単一故障で検出も代替もできません。v2.4 で独立バックストップを検討する項目として残っています。

Sheet 6_Q3ゲート保護
A1: 6_Q3 ゲート保護（R51 / D12）
A2: 2026-10-08 の Q3 破壊を受けて v3.0.0 で追加した R51（100Ω 直列）と D12（SMAJ15A ゲート−ソースクランプ）の検証。
A4: No. | B4: 項目 | C4: 手順・条件 | D4: 測定点 | E4: 設計値・判定基準 | F4: 単位 | G4: 実測値 | H4: 判定 | I4: 備考
A5: 6-1 | B5: R51 の実装・値 | C5: DMM の抵抗レンジ（無通電） | D5: TP5 − IC3.10 | E5: 100Ω ±5%。0-10 と同じ項目。本フェーズの前提条件として再確認する | F5: Ω
A6: 6-2 | B6: D12 の向きと健全性 | C6: DMM のダイオードレンジ（無通電） | D6: TP5 − TP10 | E6: TP5 ＋ で OL、逆向きで 0.6〜0.9V。0-11 と同じ項目 | F6: V
A7: 6-3 | B7: 通常動作時の非導通 | C7: VBUS 29.4V で運転中。4-3 の Vgs を確認 | D7: TP5 − TP10 | E7: Vgs 11.8〜12.0V < SMAJ15A の Vbr min 16.7V。D12 が通常動作では導通しないこと | F7: V
A8: 6-4 | B8: ゲート電流への影響 | C8: 4-4 の立ち上がり時間を R51 挿入前（v2.1.1 の 2 号機データ）と比較 | D8: TP10 | E8: 有意差がないこと。τ = 100Ω × Ciss 2.7nF = 0.27µs は 74ms に対し無視できる | F8: ms
A9: 6-5 | B9: 短絡時の Vgs クランプ（任意） | C9: ★ MDDS30 とパックを外し、電流制限 0.5A で VBUS 29.4V。Ch1 = TP5、Ch2 = TP10、時間軸 1µs/div でトリガをかけ、Vout − GND を 1Ω 程度で短絡する | D9: TP5 − TP10 | E9: Vgs が ±20V（Q3 の定格）を超えないこと。D12 のクランプ 17V 付近で止まるのが設計どおり | F9: V
A10: 6-6 | B10: 短絡後の健全性 | C10: 6-5 の後、Q3 の健全性を確認 | D10: TP5 / TP10 / TP4 | E10: TP5 − TP10 が非導通、TP10 − TP4 が Q3 のボディダイオード方向のみ導通。遮断時に Vout が 0V になること | F10: —
A12: ★ 6-5 は任意項目です。実施する場合は MDDS30 とパックを必ず外してください。基板側だけなら C7 47µF ＋ C11 1µF ＝ 48µF で蓄積エネルギーは 20.7mJ（29.4V）ですが、MDDS30 を繋ぐと 3628µF で 1.45J となり 70 倍になります。2026-10-08 に 1 号機の Q3 を破壊したのは後者です。
A13: ※ R51 / D12 の役割：出力短絡で Vout が急落すると、C9 ∥ C15（44nF、GATE−GND 間）がゲートを 41V 付近に保持し、Vgs が Q3 の定格 ±20V を超えます。R51 100Ω がその 44nF をゲートから切り離し、D12（SMAJ15A）が Q3 の Ciss 2.7nF（max 3.4nF）分だけをクランプする構成です。クランプが流すべき電流は 4.5A（R51 なし）から 0.58A（R51 あり、300ns 崩壊・Ciss max の最悪ケース）へ 7.8 分の 1 に下がります。
A14: ※ 主因は IC3 内部クランプの電流能力です。LM5060 のデータシートは GATE−OUT 16.8V を I = 0.1mA でしか規定しておらず、0.35A 級のシンクは想定されていません。当初ループインダクタンスを主因と説明しましたが、数値を詰めると二次要因でした（40nH で 0.35A を立ち上げるのに 7ns、崩壊時間 4µs に対し 3 桁小さい）。
A15: ※ D12 は Q3 の足元に配置する指示です。遠くに置くと D12 自身が「Rz 1Ω だが L 40nH 越し」のクランプになり、速い崩壊（300ns 級）で同じ問題が再発します。
A16: ※ ファームウェア #13（2ms で遮断）は「電流制限された電源での持続的な短絡」「配線の半短絡」を対象とします。コンデンサ放電による µs オーダーの事象には間に合わないため、そちらは R51 / D12 のハードウェアで受けます。両者は役割分担であって冗長ではありません。

Sheet 7_熱特性
A1: 7_熱特性
A2: 熱電対は Q1 と Q3 のパッケージ表面に貼る。TH1 / TH2 は部品本体ではなく NTC の抵抗値から温度を換算する（サーマルカメラは放射率で大きく外れる）。R11 はサーマルカメラで測る。
A4: No. | B4: 項目 | C4: 手順・条件 | D4: 測定点 | E4: 設計値・判定基準 | F4: 単位 | G4: 実測値 | H4: 判定 | I4: 備考
A5: 7-1 | B5: 筐体内周囲温度 | C5: 実機を筐体に組み込み、走行後に測定 | D5: 筐体内 | E5: 記録のみ（T_trip / T_hard 決定の根拠） | F5: ℃
A6: 7-2 | B6: 通常走行 Q1 温度 | C6: 8A 走行時、熱電対 Ch1 | D6: Q1 パッケージ | E6: 周囲＋1.3℃ 程度（下表参照。パッド→周囲 26.1K/W × 51mW） | F6: ℃
A7: 7-3 | B7: 通常走行 Q3 温度 | C7: 同時測定、熱電対 Ch2 | D7: Q3 パッケージ | E7: 周囲＋4.9℃ 程度（23.9K/W × 0.21W） | F7: ℃
A8: 7-4 | B8: 通常走行 TH1 温度 | C8: TH1 の抵抗から換算 | D8: TH1 | E8: Q1 / Q3 と 2〜3℃ 以内。T_trip 95℃ に対し 25℃ 以上の余裕 | F8: ℃
A9: 7-5 | B9: ストール時 Q1 温度 | C9: 車輪を押さえて 25A、熱電対 Ch1 | D9: Q1 パッケージ | E9: 周囲＋14.7℃ 程度（2 パック並列、12.5A/個）。★ 単一パック運転では＋59℃ になる | F9: ℃
A10: 7-6 | B10: ストール時 Q3 温度 | C10: 同時測定、熱電対 Ch2 | D10: Q3 パッケージ | E10: 周囲＋54℃ 程度（23.9K/W × 2.25W）。Q3 は全電流を単独で流す | F10: ℃
A11: 7-7 | B11: ストール時 TH1 温度 | C11: TH1 の抵抗から換算 | D11: TH1 | E11: 記録のみ。7-5 / 7-6 とのオフセットが判定対象 | F11: ℃
A12: 7-8 | B12: ストール電流 | C12: 同上、クランプメータ | D12: 入力配線 | E12: 25A 前後 | F12: A
A13: 7-9 | B13: 遮断までの時間 | C13: 7-5 を継続し、ファームウェアが遮断するまで | D13: TP10 / TP28 | E13: 記録のみ。T_trip 95℃ 到達までの時間 | F13: 秒
A14: 7-10 | B14: R11 フランジ温度 | C14: チョッパ連続導通（32.2V で 5.2W）、サーマルカメラ。★ 120℃ を超えたら即中止 | D14: R11 フランジ | E14: ★ 判定ではなく記録。下表の熱抵抗から平衡は 150℃ を超えるため、平衡させずに中止する | F14: ℃
A15: 7-11 | B15: 同時の TH2 温度 | C15: TH2 の抵抗から換算 | D15: TH2 | E15: R11 の上昇を追従して検出すること。これが v3.0.0 で TH2 を追加した目的 | F15: ℃
A16: 7-12 | B16: 同時の TH1 温度 | C16: TH1 の抵抗から換算 | D16: TH1 | E16: ほぼ周囲温度のまま（v2.0.0 実測で確認済み。TH1 は R11 の過熱を検出しない） | F16: ℃
... A21: 7-17 | B21: R70（シャント）の温度 | C21: 25A ストール時、サーマルカメラまたは熱電対 | D21: R70 本体 | E21: 記録のみ。25A で 0.31W、30A で 0.45W（2512 / 3W 定格）。周囲＋40℃ 以内を目安 | F21: ℃
A23: 温度オフセット（自動計算）
A24: 項目 | B24: 計算式 | C24: 値 | D24: 設計想定 | E24: 判定
A25: Q1 − TH1（ストール時） | B25: 7-5 − 7-7 | C25: =IF(COUNT(G9,G11)=2,G9-G11,"") | D25: 2〜3℃（TH1 は Q1〜Q3 の各ドレインパッドから約 1mm）
A26: Q3 − TH1（ストール時） | B26: 7-6 − 7-7 | C26: =IF(COUNT(G10,G11)=2,G10-G11,"") | D26: 5〜10℃（Q3 の損失が大きいぶん開く）
A27: R11 − TH2（チョッパ動作時） | B27: 7-10 − 7-11 | C27: =IF(COUNT(G14,G15)=2,G14-G15,"") | D27: 数十℃（TH2 は R11 から 5mm 離してある）
A28: R11 − TH1（チョッパ動作時） | B28: 7-10 − 7-12 | C28: =IF(COUNT(G14,G16)=2,G14-G16,"") | D28: 大きく開く（TH1 は R11 を検出しない）
A30: 銅箔の熱抵抗（.kicad_pcb の実形状から数値解析）
A31: 測定点 | B31: 熱抵抗（パッド→周囲） | C31: 初版基板 | D31: v3.0.0 基板 | E31: 備考
A32: Q1 ドレインタブ | B32: K/W | C32: 29.1 | D32: 26.1 | E32: 裏面 VBUS 放熱ベタの拡大（29.0 × 29.0mm、783mm²）による
A33: Q2 ドレインタブ | B33: K/W | C33: 28.4 | D33: 25.9 | E33: 同上
A34: Q3 ドレインタブ | B34: K/W | C34: 24.0 | D34: 23.9 | E34: ほぼ変化なし（元から Vout ベタが広い）
A35: R11 フランジ | B35: K/W | C35: 27.4 | D35: 27.3 | E35: 変化なし。R11 の放熱は元から専用ベタ
A37: 損失と温度上昇の予測（上の熱抵抗から算出）
A38: 条件 | B38: 電流 | C38: 1 素子の損失 | D38: Q1 / Q2 の上昇 | E38: Q3 の上昇
A39: 通常走行（2 パック） | B39: 8A 合計 / 4A 個別 | C39: Q1 51mW / Q3 0.21W | D39: ＋1.3℃ | E39: ＋4.9℃
A40: ストール（2 パック） | B40: 25A 合計 / 12.5A 個別 | C40: Q1 0.56W / Q3 2.25W | D40: ＋14.7℃ | E40: ＋54℃
A41: ストール（単一パック） | B41: 25A すべて片側 | C41: Q1 2.25W / Q3 2.25W | D41: ＋59℃ | E41: ＋54℃
A42: ヒューズ定格（参考） | B42: 30A | C42: Q3 3.24W | D42: — | E42: ＋77℃
A44: ※ Q1 / Q2 / Q3 は v3.0.0 で CSD18540Q5B（TI、在庫終了）から BSC028N06NS（Infineon、LCSC C148250、PG-TDSON-8 / SuperSO8）に変更しました。基板の footprint「TDSON-8-1」は Infineon の PG-TDSON-8 用に描かれたものなので幾何学的に一致します。ピン配置は 1-3 = Source / 4 = Gate / 5-8 = Drain（露出パッド）。★ 末尾に SC が付く BSC028N06NSSC（LCSC C534317）は露出パッドがソースの別品種なので絶対に使わないこと。
A45: ※ 上表は .kicad_pcb の実形状から銅箔の面内熱伝導・FR4 の板厚方向伝導・両面 8W/m²K の自然対流を連立させて解いた値です。パッケージの接合部−ケース間（BSC028N06NS の R_θJC 0.9K/W typ・1.5K/W max）は含みません。損失 2.25W でも接合部はケースより 3.4℃ 高いだけなので、実質はパッケージ表面温度の予測値として使えます。
A46: ※ BSC028N06NS の Tj max は 150℃ で、CSD18540Q5B / NTMFS5C628NL の 175℃ より 25℃ 低くなります。周囲 65℃・2 パックのストールでも Q3 の接合部は 65 ＋ 54 ＋ 1.5 × 2.25 ≒ 122℃（余裕 28℃）、単一パックの最悪でも Q1 が 127℃（余裕 23℃）です。さらに TH1 は Q1〜Q3 の各ドレインパッドから約 1mm にあるためほぼケース温度を読み、ストール時のケース 119℃ は T_hard 115℃ を超えるので、ファームウェア #4 が接合部 150℃ のはるか手前で遮断します。ファームが死んだ場合も R42 / Q6 が 93ms で EN を落とすため到達しません。
A47: ※ Rds_on は BSC028N06NS の max 2.8mΩ（Vgs 10V / 25℃、typ 2.5mΩ）に温度係数を掛け、60℃ で 3.2mΩ、100℃ で 3.6mΩ として計算しました（60V トレンチ MOSFET の一般値、100℃ で ×1.3）。実測が上表より高い場合は、まず Vgs（4-3）が 10V 以上出ているかを確認してください。
A48: ★ 単一パック運転のストールが最悪条件です。Q1 または Q2 が 25A を単独で流すと＋59℃ になり、2 パック並列（＋14.7℃）の 4 倍になります。片方のパックを外した状態で高負荷をかけないでください。
A49: ※ R11 の熱抵抗 27.3K/W は、v2.1.1 の実測（32.5V / 5.28W で 120℃ に達しても平衡せず → 18℃/W 超）と整合します。5.2W の連続導通では平衡が 周囲＋142℃ となり、周囲 25℃ でも 167℃ で最高使用温度 150℃ を超えます。高温域では放射と自然対流の強化で実効熱抵抗が下がるため実際はこれより低くなりますが、「連続導通では 150℃ を超える」という結論は変わりません。
...

Sheet 8_ブレーキチョッパ
A1: 8_ブレーキチョッパ
A2: v2.1.1 の fail-off 構成（Q5 による PNP 反転段）をそのまま維持。R10 の取り外しは不要です。v3.0.0 では CHOP_SENSE によるマイコン側の監視が加わりました。
A4: No. | B4: 項目 | C4: 手順・条件 | D4: 測定点 | E4: 設計値・判定基準 | F4: 単位 | G4: 実測値 | H4: 判定 | I4: 備考
A5: 8-1 | B5: 12V レール | C5: Vout 29.4V、DMM | D5: TP8 / TP3 | E5: 12V ±5%（11.4〜12.6V） | F5: V
A6: 8-2 | B6: 基準電圧 | C6: 同上 | D6: TP11 / TP3 | E6: 2.495V ±0.5% | F6: V
A7: 8-3 | B7: 分圧ノード | C7: 同上 | D7: TP15 / TP3 | E7: Vout × 0.0774（29.4V で 2.28V） | F7: V
A8: 8-4 | B8: Q5 コレクタ（OFF） | C8: チョッパ非動作時 | D8: TP23 / TP3 | E8: Vout × 0.0077（29.4V で 226mV）。R14 経由で Chopper_Sense の電位が分圧されて現れる | F8: V
A9: 8-5 | B9: Q4 ゲート（OFF） | C9: 同上 | D9: TP9 / TP12 | E9: Vout × 0.0070（29.4V で 206mV）。8-4 の値を R12 / R13 で分圧した値 | F9: V
A10: 8-6 | B10: Q4 ドレイン（OFF） | C10: 同上 | D10: TP21 / TP12 | E10: Vout と同電位 | F10: V
A11: 8-7 | B11: チョッパ動作点 | C11: 電源電圧を 30V から慎重に上げる | D11: TP10 / TP19 | E11: 32.2V でクランプ開始 | F11: V
A12: 8-8 | B12: チョッパ復帰点 | C12: 電圧を下げる | D12: TP10 / TP19 | E12: 30.8V で復帰 | F12: V
A13: 8-9 | B13: Q5 コレクタ（ON） | C13: チョッパ動作中 | D13: TP23 / TP3 | E13: 11.9V 付近 | F13: V
A14: 8-10 | B14: Q4 ゲート（ON） | C14: 同上 | D14: TP9 / TP12 | E14: 10.9V 付近 | F14: V
A15: 8-11 | B15: チョッパ電流 | C15: R11 両端電圧から算出、または電源の電流表示 | D15: R11 / TP21 | E15: 0.161A 前後（32.2V / 200Ω） | F15: A
A16: 8-12 | B16: R11 のフランジ温度 | C16: 8-7 の状態を数十秒継続 | D16: R11 フランジ | E16: 周囲＋20℃ 程度（数十秒時点）。連続導通では 150℃ を超えるため長時間続けない | F16: ℃
... A18: 8-14 | B18: CHOP_SENSE の読み（ON） | C18: チョッパ動作中 | D18: 同上 | E18: 0V 付近（＝ L）。ファームウェア #6 は Low をチョッパ動作中と判定する | F18: V
A20: ※ 8-7 は OVP 動作点 34.0V に近いため、電圧はゆっくり上げてください。確認できたら速やかに下げます。
A21: ※ v2.1.1 で fail-off 構成（Q5 による PNP 反転段）になったため、v2.0.0 で行っていた「R10 を外してチョッパを無効化する」手順は不要です。LM397 の故障・12V レール喪失・Q5 のオープン故障・R21 の断線のいずれでも Q4 はオフになります。ただし VREF の崩壊と Q5 / Q4 の短絡故障は fail-on のままで、そこを v3.0.0 では TH2 と #5 / #6 で受けます。
A22: ※ 8-4 / 8-5 は 0V ではありません。R14（1MΩ）がヒステリシス用に Chopper_Sense と Q5 のコレクタを繋いでいるため、チョッパ OFF でも Chopper_Sense の電位が R14 と R12+R13 で分圧されて現れます。Chopper_Sig = Vout × 0.0775 × 110k/(1000k+110k) = Vout × 0.0077。
A23: ※ この性質を使うと TP23 の実測値から Vout を逆算できます（Vout ≒ TP23 ÷ 0.0077）。32.2V まで上げなくても、分圧回路と R14 の結線が設計どおりかを低電圧のまま検証できます。
A24: ※ 8-13 / 8-14 は v3.0.0 で追加した項目です。CHOP_SENSE（R36 1MΩ / R37 100kΩ の ÷11 分圧）はテストポイントを持たないため、IC6.10 または C35 の上側端子で測るか、SWD で ADC の生値を読んでください。
A25: ※ R11 の最終値は 9-6 / 9-7 の回生プロファイル実測で決めます。候補と周囲 65℃ での連続導通時の平衡温度（熱抵抗 27.3K/W）：200Ω → 207℃ / 330Ω → 151℃ / 470Ω → 126℃ / 680Ω → 108℃。引ききるのに必要な制動時間は 200Ω で 2.5 秒、470Ω で 5.9 秒です。

Sheet 9_走行時総合
A1: 9_走行時総合
A2: 実走行状態での確認。9-6 / 9-7 は R11 の最終値とファームウェア #6 の閾値を決める項目で、本シートの最優先事項です。
A4: No. | B4: 項目 | C4: 手順・条件 | D4: 測定点 | E4: 設計値・判定基準 | F4: 単位 | G4: 実測値 | H4: 判定 | I4: 備考
A5: 9-1 | B5: バス電圧リプル | C5: 走行中、AC カップリング | D5: TP4 / TP17 | E5: 18kHz 成分が 100mV 以下 | F5: mV
A6: 9-2 | B6: Q1 ゲート波形 | C6: 走行中、Q1 のゲートを観測 | D6: Q1 ゲート | E6: 25ms 周期のリフレッシュのみ。周期外の落ち込みが無いこと | F6: —
A7: 9-3 | B7: 順方向降下 | C7: 8A 走行時、ツイストペアで差動測定 | D7: TP13 − TP4 | E7: 17mV 前後 | F7: mV
A8: 9-4 | B8: 遮断時の Vout | C8: 走行中にスイッチ OFF | D8: TP10 / TP19 | E8: 負に振れないこと（C7 が支える） | F8: V
A9: 9-5 | B9: 給電パックの判別 | C9: 走行中 | D9: TP13 / TP14 | E9: 電圧の高い側から給電されること | F9: V
A10: 9-6 | B10: 回生プロファイル | C10: 制動時、Ch1 = TP21（GND:TP12）、Ch2 = TP10 | D10: TP21 / TP12 | E10: 導通時間とデューティを記録。R11 の最終値と #6 の閾値の判断材料 | F10: ms
A11: 9-7 | B11: 制動時の最大 Vout | C11: 同時観測 | D11: TP10 / TP19 | E11: 34.0V（OVP）に達しないこと。余裕があれば R11 を 330Ω / 470Ω に上げられる | F11: V
A12: 9-8 | B12: Vout 経路の電圧降下 | C12: 8A 走行時と 25A ストール時、差動測定 | D12: TP10 − J3 の + 端子 | E12: 8A / 25A の期待値は ★要再解析。★ 2026-10-14 以降に R70（0.5mΩ / 2512）が Q3 ソースと /Vout の間に挿入され、Vout ベタが切り欠かれたため旧値 1.024mΩ（8A で 8.2mV、25A で 25.6mV）は使えない。なお TP10 は R70 の下流なので本測定に R70 の 0.5mΩ は含まれない | F12: mV
A13: 9-9 | B13: GND 経路の電圧降下 | C13: 同上 | D13: TP19 − J1 / J2 の − 端子 | E13: 8A で 7.8mV、25A で 24.4mV（実測検証 0.975mΩ、2 パック）。単一パックでは 1.398mΩ → 35mV | F13: mV
A14: 9-10 | B14: VBUS_SENSE の走行時精度 | C14: 走行中、SWD で ADC 値を読み TP4 の実測と比較 | D14: TP4 / IC6.8 | E14: 誤差 ±2% 以内。リプルによる読み値の揺れも記録 | F14: V
A15: 9-11 | B15: VOUT_SENSE の走行時精度 | C15: 同上 | D15: TP10 / IC6.9 | E15: 同上。★ C34 は 1nF なので #13 の 2ms 検出に間に合う時定数 | F15: V
A16: 9-12 | B16: チョッパ ON 積算の実測 | C16: 9-6 の制動を数回繰り返し、SWD で積算値を読む | D16: SWD | E16: #6 の閾値を決めるための記録。制動 1 回あたりの積算増分を記録する | F16: —
... A18: 9-14 | B18: IC5 バッファ出力 | C18: VBUS 29.4V、差動測定 | D18: J7 pin3 − J7 pin2 | E18: 1.601V（29.4V × 57.6kΩ ÷（1MΩ ＋ 57.6kΩ））、±3%。換算係数 18.36 V/V。R76 1kΩ ＋ C66 1µF で fc 159Hz | F18: V
A20: ※ 9-1 が 100mV を大きく超える場合、C5 のリプル電流定格（18kHz で約 1.06A）に対する余裕を再検討してください。
A21: ※ 9-2 で周期外の落ち込みがあれば、リプルによる逆流誤検出が起きています。
A22: ※ 9-8 / 9-9 は v3.0.0 で追加した項目です。基板図の銅箔形状から抵抗ネットワークを解いた値（Q3 ソース → J3.1 が 1.024mΩ、J3 の GND → 両パックの − 端子が 0.975mΩ）の裏取りで、実測が大きく上回る場合は銅箔ではなくコネクタのはんだ付けを疑ってください。 ★ 2026-10-21 追記：R70（0.5mΩ）が Q3 ソース → /Vout に挿入されたため、Q3 ソース → J3.1 の全体は 銅箔 ＋ 0.5mΩ ≒ 1.5mΩ に増えた。TP10 は R70 の下流なので 9-8 の実測には R70 分は現れないが、ベタ形状が変わったため期待値そのものを再解析すること。
A23: ※ 9-9 の 30A 時の損失は 0.88W（GND 側）＋ 0.92W（Vout 側）＝ 1.8W で、基板全体に広く分散します。局所的な過熱にはなりません。 ★ 2026-10-21 追記：ただし R70（0.5mΩ / 2512 / 3W）は 30A で 0.45W、25A で 0.31W を単独で負担するため、ここだけは局所的です（7-17 で確認）。
A24: ※ 9-7 で OVP に達する場合は R11 を引ききれていません。150Ω または 100Ω への変更を検討してください。200Ω は制動時間 2.5 秒以上を前提にした値です。回生エネルギーは並進 4.5J ＋ ロータ慣性 約 1.8J ＝ 約 6.3J と見積もっています（ロータ慣性は推定値）。
A25: ※ 9-12 の結果で #6 の閾値を決めます。制動 1 回の積算増分を N とすると、閾値は「連続導通を 10 秒以内に止める値」と「正常な制動を数回続けても誤発火しない値」の間に取ります。

Sheet 10_GND分離
A1: 10_GND 分離
A2: C5（VBUS 側バルクコンデンサ）のマイナス端子での一点接続が機能しているかの検証。v3.0.0 では ADC の基準電位がここに乗るため、v2.1.1 より重要度が上がっています。
A4: No. | B4: 項目 | C4: 手順・条件 | D4: 測定点 | E4: 設計値・判定基準 | F4: 単位 | G4: 実測値 | H4: 判定 | I4: 備考
A5: 10-1 | B5: 制御GND−大電流GND | C5: チョッパ動作中、差動測定 | D5: TP3 − TP12 | E5: 数十 mV 以内 | F5: mV
A6: 10-2 | B6: 同上（通常走行時） | C6: 8A 走行中 | D6: TP3 − TP12 | E6: 7.8mV 以下（経路全体の抵抗 0.975mΩ × 8A が原理上の上限） | F6: mV
A7: 10-3 | B7: 同上（ストール時） | C7: 25A ストール中 | D7: TP3 − TP12 | E7: 24.4mV 以下（同 × 25A）。単一パック運転では 35mV 以下 | F7: mV
A8: 10-4 | B8: DC 島の等電位性 | C8: 25A ストール中、差動測定 | D8: TP2 / TP3 / TP17 / TP32 の相互 | E8: 相互に 1mV 以内。DC 島には大電流が流れないため | F8: mV
A9: 10-5 | B9: AC 島の内部降下 | C9: 同上 | D9: TP1 / TP12 / TP18 / TP19 の相互 | E9: 数 mV〜数十 mV。島内の IR ドロップそのものなので、値の大小ではなく 10-4 との差が判定対象 | F9: mV
A10: 10-6 | B10: 一点接続の位置確認 | C10: 無通電、目視と導通 | D10: C5 の GND パッド | E10: C5 の GND パッド直下に 0.3〜0.5mm ビアが 8 本あり、それが唯一のブリッジであること。設計解析では確認済み（記録のみ） | F10: —
A11: 10-7 | B11: ADC の基準電位の健全性 | C11: 25A ストール中、SWD で TH1_SENSE の ADC 値を読む | D11: IC6.7 / TP26 | E11: 無負荷時（7-4）と同じ温度を示すこと。10mV 以上ずれるなら GND 分離が効いていない | F11: ℃
A12: 10-8 | B12: アナログ島の等電位性 | C12: 25A ストール中、差動測定 | D12: J7 pin2 − TP32 | E12: 1mV 以内。超えるならネットタイ NT1 以外の経路で ANALOG_SENSE_GND が GND に繋がっている | F12: mV
A14: GND テストポイントと島の対応（v3.0.0 基板図から確認）
A15: テストポイント | B15: ネット | C15: 島 | D15: 座標 (mm) | E15: 用途
A16: TP2 | B16: GND | C16: DC 島 | D16: (117.84, 81.79) | E16: EN / TIMER 測定の基準（IC3 の GND 側）
A17: TP3 | B17: GND | C17: DC 島 | D17: (109.64, 46.34) | E17: チョッパ制御系の基準。10-1〜10-3 の DC 側
A18: TP17 | B18: GND | C18: DC 島 | D18: (104.83, 116.49) | E18: VBUS 測定の基準
A19: TP32 | B19: GND | C19: DC 島 | D19: (104.80, 92.84) | E19: 3.3V / MCU 系の基準。v3.0.0 で追加
A20: TP1 | B20: GND | C20: AC 島 | D20: (142.18, 140.47) | E20: J1 / J2 側
A21: TP12 | B21: GND | C21: AC 島 | D21: (175.20, 48.94) | E21: チョッパ負荷側。10-1〜10-3 の AC 側
A22: TP18 | B22: GND | C22: AC 島（裏面のみ） | D22: (131.71, 82.64) | E22: ゲート波形（TP5）の基準
A23: TP19 | B23: GND | C23: AC 島 | D23: (168.34, 66.29) | E23: Vout 測定の基準
A24: （TP なし） | B24: ANALOG_SENSE_GND | C24: アナログ島 | D24: NT1 = (178.66, 69.55) | E24: U3 / IC5 / R72 / C65〜C68 / J7 pin2 の基準。ネットタイ NT1 一点で GND に接続。★ 2026-10-21 追加。TP が無いので J7 pin2 で測る
A26: ※ 上表は .kicad_pcb のゾーン塗りつぶしをラスタライズし、連結成分解析で確認したものです。10-1〜10-3 の「DC 島 − AC 島」を測るには DC 側から 1 点、AC 側から 1 点を選びます。v2.1.1 の TP3 − TP12 の組み合わせはそのまま有効です。 ★ 2026-10-21 追記：2026-10-14 以降に R70 と ANALOG_SENSE_GND 島（NT1）が追加され、TP3 / TP18 / TP19 が移動したため、ゾーンの連結成分解析は現基板で再実行すること。TP18 の「裏面のみ」も再確認が必要。
A27: ※ 10-2 / 10-3 の上限値は「J3 の GND から両パックの − 端子までの経路全体の抵抗が 0.975mΩ（2 パック）／1.398mΩ（単一パック）」という解析結果から導いた原理上の上限です。TP3 − TP12 はその経路の一部しか見ないため、実測はこれより小さくなるのが正常です。超える場合は一点接続以外の経路（2 つ目のブリッジ）が存在します。
A28: ※ 10-4 が 1mV を超える場合、DC 島に大電流経路が混入しています。設計仕様書 7_レイアウト指示 の「DC 島に置く部品」一覧を確認し、AC ベタに GND を落としている部品がないか探してください。1 つでも落ちていると分割が無効になります。
A29: ※ 10-7 は v3.0.0 で追加した最も実務的な項目です。GND 分離の目的は「ADC の基準電位を大電流の IR ドロップから切り離すこと」なので、分離が効いているかは最終的に ADC の読みで判定します。
A30: ※ 想定を超える場合、GND の引き回しを見直してください。次版での改善項目になります。

Sheet 11_外部スイッチ・LED
A1: 11_外部スイッチ・LED
A2: LED 付き非常停止スイッチ（5 ピン、1NO1NC）と F3（PPTC）の確認。ハーネスは v2.1.1 のまま流用できますが、pin3 / pin4 が繋がるネットが 3.3V 系ロジックに変わりました。
A4: No. | B4: 項目 | C4: 手順・条件 | D4: 測定点 | E4: 設計値・判定基準 | F4: 単位 | G4: 実測値 | H4: 判定 | I4: 備考
A5: 11-1 | B5: 非常停止の遮断 | C5: ボタンを押す | D5: TP10 / TP19 | E5: Vout が 0V になること | F5: V
A6: 11-2 | B6: 復帰 | C6: ひねって解除 | D6: TP10 / TP19 | E6: Vout が復帰すること | F6: V
A7: 11-3 | B7: 接点の導通抵抗 | C7: 無通電、スイッチ解除状態 | D7: J4 pin3 − pin4 | E7: 1Ω 以下 | F7: Ω
A8: 11-4 | B8: 接点電流 | C8: 運転中 | D8: J4 pin3 − pin4 | E8: 1.22mA（2.68V ÷ 2.2kΩ）。接点の酸化皮膜対策として 1mA 以上を確保している | F8: mA
A9: 11-5 | B9: LED 電流（34V） | C9: Vout を 34V に設定し、J4 pin1 の電流を測定 | D9: J4 pin1 | E9: 40mA 以下が望ましい | F9: mA
A10: 11-6 | B10: LED 電流（19.5V） | C10: Vout を 19.5V に設定 | D10: J4 pin1 | E10: 記録のみ（電圧依存性の確認） | F10: mA
A11: 11-7 | B11: F3 の電圧降下 | C11: 11-5 と同時に測定 | D11: Vout − J4 pin1 | E11: LED 電流 × 1.6〜15Ω | F11: mV
A12: 11-8 | B12: LED 線短絡時のトリップ | C12: ★ 電流制限付き電源で J4 pin1 − pin2 を短絡 | D12: J4 | E12: F3 がトリップすること。1 秒以内 | F12: 秒
A13: 11-9 | B13: F3 の復帰時間 | C13: 短絡を解除し、LED が再点灯するまで | D13: 外部 LED | E13: 記録のみ | F13: 秒
A14: 11-10 | B14: EN_FB の読み戻し | C14: 非常停止を押す／解除する | D14: IC6.15 / TP7 | E14: PA8 が TP7 の状態（2.68V ↔ 78mV）を R41 10kΩ 経由で読めること。#12 の STOP 判定と復帰に使う | F14: V
A16: ★ 11-8 は意図的な短絡試験です。必ず電流制限付き電源で実施し、パックは接続しないでください。
A17: ※ 11-5 が 40mA を超える場合、F3 を 1206L020/60NR（ホールド電流 200mA）に変更してください。筐体内 65℃ ではホールド電流が 25℃ 定格の 6 割程度まで下がります。
A18: ※ F3（1206L010/60NR）の諸元：ホールド 100mA / トリップ 250mA / Vmax 60V / 正常時抵抗 1.6〜15Ω / 動作温度 −40〜85℃。
A19: ※ 外部 LED は Vout から駆動されるため、非常停止・サーマル遮断・OVP・UVLO・マイコンによる遮断のいずれで遮断されても消灯します。スイッチ位置ではなく実際の出力を示します。
A20: ※ 11-10 は v3.0.0 で追加した項目です。J4 のハーネスは v2.1.1 のまま流用できますが、pin3 / pin4 が繋がるネットが 3.3V 系ロジック（EN_SWITCH / EN）に変わりました。
A21: ※ J4 ハーネスが Vout に短絡した場合、D8（5V ESD）が先にクランプして電流を全部引き受けます。D8 はこの間クランプ 9V 付近で 100mA＝約 0.9W を負担するため破壊される前提の犠牲部品です。ハーネス短絡の後は D8 を交換してください。

Sheet 12_量産工程
A1: 12_量産工程（300 枚ロット）
A2: 300 枚ロットの量産工程。方針は「全数は短縮版、抜取りでフル試験」。J6（SWD ヘッダ）は量産では未実装とし、スルーホールにポゴピンを当てて書き込む。試作（v3.0.0 初号〜）では J6 を PCBA 実装しているので、本シートの治具は量産ロットから適用する。
A4: 前提条件
A5: 項目 | B5: 内容
A6: ロット数量 | B6: 300 枚
A7: J6（SWD ヘッダ） | B7: ★量産では未実装（DNP）。発注時に「J6 はスルーホールを塞がずに未実装」と明示すること。溶融はんだで穴が埋まるとポゴピンが入らない
A8: JP1 | B8: 基板パターンのみ。★量産では絶対にブリッジしない（ブリッジするとマイコンによる遮断が一切効かない）
A9: 電源の供給 | B9: J1（XT60）に 24V / 電流制限 0.2A の可変電源を接続する。IC4 経由で 3.3V レールが立ち、MCU が動く。VBUS 経由にすることで IC4 の動作も同時に検証できる
A10: J4 ループバックプラグ | B10: JST XA 4 極のハウジングに pin3 − pin4 を短絡した線を入れた治具。非常停止スイッチの「解除」を模擬する。抜き差しで P-7 の非常停止試験ができる
A11: 全数検査 | B11: P-1〜P-7 の 7 項目。1 枚あたり約 100 秒
A12: 抜取り検査 | B12: 初期流動 5 枚（レベル A）＋ 以降 30 枚ごとに 1 枚（レベル B、計 10 枚）＝ 合計 15 枚
A13: 工数の目安 | B13: 全数 300 枚 × 100 秒 ≒ 8.5 時間 ／ 抜取り A 5 枚 × 60 分 ＝ 5 時間 ／ 抜取り B 10 枚 × 20 分 ≒ 3.3 時間 ／ 合計 約 17 時間（約 2 人日）
A15: 工程フロー（1 枚あたり）
A16: 順 | B16: 工程 | C16: 内容 | D16: 所要
A17: 1 | B17: 受入 | C17: PCBA から入荷。ロット番号・数量・製造日を記録 | D17: —
A18: 2 | B18: 外観（P-1） | C18: ルーペで目視 | D18: 20 秒
A19: 3 | B19: 出力短絡（P-2） | C19: DMM 抵抗レンジ | D19: 8 秒
A20: 4 | B20: 通電（P-3 / P-4） | C20: J1 に 24V 投入。3.3V レールと「Vout が出ないこと」を確認 | D20: 17 秒
A21: 5 | B21: 書き込み（P-5） | C21: ポゴピン治具を押し当て、CLI を実行。UID とログを記録 | D21: 15 秒
A22: 6 | B22: 運転確認（P-6） | C22: J4 ループバックを挿す。Vout と LED1 を確認 | D22: 12 秒
A23: 7 | B23: 非常停止（P-7） | C23: ループバックを抜く。Vout が落ちることを確認 | D23: 5 秒
A24: 8 | B24: 電源断 | C24: 24V を落とし、MDDS30 側を放電（本工程では負荷未接続のため不要） | D24: —
A25: 9 | B25: 抜取り判定 | C25: 該当枚（初期 5 枚 ＋ 30 枚ごと）なら抜取り検査へ回す | D25: —
A26: 10 | B26: ラベル・梱包 | C26: 基板に UID 下 6 桁とロット番号を記載したラベルを貼る | D26: 15 秒
A28: 全数検査項目（短縮版）
A29: No. | B29: 項目 | C29: 手順・条件 | D29: 測定点 | E29: 設計値・判定基準 | F29: 単位 | G29: 実測値 | H29: 判定 | I29: 備考
A30: P-1 | B30: 外観 | C30: ルーペ（8〜10倍、LED付）で全面 | D30: 基板全体 | E30: ブリッジ・未はんだ・欠品・向き違いが無いこと。重点は IC6（TSSOP-20、0.65mm ピッチ）、IC4（SOT-23-6）、Q1〜Q3（PG-TDSON-8）。★ J6 のスルーホール 5 個がはんだで塞がっていないこと。★ JP1 がブリッジされていないこと、U3（TSSOP-8、0.65mm ピッチ）、IC5（SOT-23-5）、R70（2512 シャント、ケルビンパッドの向き）。★ R73 / C64 / C69 が未実装（DNP）であること。★ R74 / R75（0Ω）が実装されていること | F30: —
A31: P-2 | B31: 出力短絡 | C31: DMM 抵抗レンジ（無通電） | D31: TP10 − TP19 | E31: 数百Ω以上で、C7 / C11 の充電により表示が上昇し続けること。数Ωで止まったら Vout − GND の短絡 | F31: Ω
A32: P-3 | B32: 3.3V レール | C32: J1 に 24V 投入（電流制限 0.2A）、J4 は未接続 | D32: TP24 − TP32 | E32: 3.21〜3.41V（3.307V ±3%）。同時に電源の電流表示が 5mA 未満であること | F32: V
A33: P-4 | B33: ★未書込みで Vout が出ないこと | C33: P-3 と同じ状態 | D33: TP10 − TP19 | E33: 0.1V 未満。★これがフェイルセーフの全数検証。Vout が出たら重大不適合 | F33: V
A34: P-5 | B34: 書き込み＋ベリファイ | C34: ポゴピン治具を J6 のスルーホールに押し当て、書き込みスクリプトを実行 | D34: J6 pin1〜5 | E34: CLI が PASS を返すこと。UID・FW ハッシュ・RDP 設定結果がログに記録されること | F34: —
A35: P-6 | B35: 運転移行 | C35: J4 ループバックプラグを挿す | D35: TP10 − TP19 / LED1 | E35: Vout が VBUS − 0.5V 以上に立ち上がること。LED1 が点灯すること | F35: V
A36: P-7 | B36: ★非常停止 | C36: J4 ループバックプラグを抜く | D36: TP10 − TP19 | E36: Vout が 0.5V 未満に落ちること。★効かなければ重大不適合 | F36: V
A38: ★ P-4 と P-7 は安全に関わる項目です。どちらかが NG の基板は、原因を特定して是正するまで絶対に出荷しないでください。P-4 の NG はマイコン死亡時に出力が切れないことを、P-7 の NG は非常停止が効かないことを意味します。
A39: ※ 電源の電流制限を 0.2A にしておくことで、VBUS − GND や 3.3V − GND の短絡は P-3 の時点で CC に入って分かります。そのため DMM による短絡確認は、Q3 を守る必要がある出力側（P-2）だけに絞っています。
A40: ※ P-3 で IC4（3.3V 降圧）も同時に検証されます。3.3V を直接注入する方式だと IC4 が未検証のまま通過してしまうため、VBUS からの給電にしています。
A41: ※ P-6 で Vout が立ち上がるのは、書き込み済みマイコンが PA5 = L にし、J4 ループバックで EN 経路が閉じるためです。立ち上がりに 40〜90ms かかるので、挿してから 0.5 秒ほど待って測定してください。
A42: ※ 本工程では MDDS30 を接続しないため、Vout 側の容量は C7 47µF ＋ C11 1µF の 48µF だけです。蓄積エネルギーは 29.4V で 20.7mJ と小さく、放電手順は不要です。
A43: ※ 1 枚あたり約 100 秒（外観 20 ＋ 短絡 8 ＋ 通電 17 ＋ 書き込み 15 ＋ 運転 12 ＋ 非常停止 5 ＋ ハンドリング 25）。300 枚で約 8.5 時間です。
A45: NG 時の処置
...

Sheet 13_量産記録
A1: 13_量産記録
A2: 全数検査の 1 枚ごとの結果はスクリプトが CSV に出力する。本シートにはロット単位の集計と、抜取り検査の記録を残す。
A4: ロット記録（1 ロットにつき 1 枚このシートを複製する）
A5: 項目 | B5: 内容
A6: ロット番号
A7: 数量
A8: PCBA 受入日
A9: 書き込み実施日
A10: FW ファイル名
A11: FW ハッシュ（SHA-256 先頭16桁）
A12: RDP レベル | B12: 1
A13: 作業者
A14: 全数 合格数
A15: 全数 不合格数
A16: 抜取り A 実施枚数
A17: 抜取り B 実施枚数
A18: 総合判定
A20: 全数検査ログ（CSV）の列定義 — スクリプトが自動出力する
A21: 列 | B21: 内容 | C21: 例
A22: 1 連番 | B22: ロット内の通し番号 | C22: 001
A23: 2 日時 | B23: ISO 8601 | C23: 2026-11-05T10:23:41+09:00
A24: 3 ロット番号 | B24: 製造ロット | C24: MGPC-V300-L01
A25: 4 UID | B25: STM32 の 96bit 固有 ID（16 進 24 桁） | C25: 0A1B2C3D4E5F60718293A4B5
A26: 5 FW ファイル名 | B26: 書き込んだ hex のファイル名 | C26: mgpc_v1.0.0.hex
A27: 6 FW ハッシュ | B27: hex ファイルの SHA-256（先頭 16 桁） | C27: 3f9a1c7e2b4d8056
A28: 7 書き込み結果 | B28: PASS / FAIL | C28: PASS
A29: 8 ベリファイ結果 | B29: PASS / FAIL | C29: PASS
A30: 9 RDP | B30: 設定後のレベル | C30: 1
A31: 10 再試行回数 | B31: 0〜2 | C31: 0
A32: 11 P-1〜P-7 判定 | B32: 7 項目の OK / NG をカンマ区切り | C32: OK,OK,OK,OK,OK,OK,OK
... A34: 13 備考 | B34: NG 内容・是正内容 | C34: —
A36: 抜取り検査の記録（15 枚）
A37: No. | B37: 基板 UID 下6桁 | C37: レベル | D37: 実施日 | E37: 判定 | F37: NG 項目・是正内容
A38: 1 | C38: A
A39: 2 | C39: A
A40: 3 | C40: A
A41: 4 | C41: A
A42: 5 | C42: A
A43: 6 | C43: B
A44: 7 | C44: B
...

Sheet サマリ
A1: 設計値と実測値の比較サマリ
A2: 各シートに入力すると自動で反映されます（灰色セル）。
A4: 項目 | B4: 設計値 | C4: 実測値 | D4: 差 | E4: 判定 | F4: 備考
A5: 3.3V レール出力 | B5: 3.307 V | C5: ='1_3.3V電源'!G5 | D5: =IF(ISNUMBER(C5),C5-3.307,"")
A6: 3.3V リプル | B6: 1.0 mVpp（上限 30） | C6: ='1_3.3V電源'!G7 | D6: — | F6: グランドスプリング必須
A7: スイッチング周波数 | B7: 700 kHz | C7: ='1_3.3V電源'!G8 | D7: =IF(ISNUMBER(C7),C7-700,"") | F7: X 版の確認
A8: 3.3V 負荷（運転時） | B8: 8.0 mA | C8: ='1_3.3V電源'!G13 | D8: =IF(ISNUMBER(C8),C8-8.0,"")
A9: 3.3V 負荷（遮断時） | B9: 15.9 mA | C9: ='1_3.3V電源'!G12 | D9: =IF(ISNUMBER(C9),C9-15.9,"") | F9: EN チェーン 13mA を含む
A10: マイコン死亡時の遮断 | B10: 93 ms | C10: =2_MCU書き込みと基本動作!G23 | D10: =IF(ISNUMBER(C10),C10-93,"") | F10: R42 1MΩ × C20 100nF
A11: UVLO 遮断 | B11: 19.5 V | C11: =3_低電圧基本動作!G5 | D11: =IF(ISNUMBER(C11),C11-19.5,"")
A12: UVLO 復帰 | B12: 17.4 V | C12: =3_低電圧基本動作!G6 | D12: =IF(ISNUMBER(C12),C12-17.4,"")
A13: OVP 遮断 | B13: 34.0 V | C13: =3_低電圧基本動作!G7 | D13: =IF(ISNUMBER(C13),C13-34,"")
A14: OVP 復帰 | B14: 30.1 V | C14: =3_低電圧基本動作!G8 | D14: =IF(ISNUMBER(C14),C14-30.1,"")
A15: EN 電圧（運転時） | B15: 2.68 V | C15: =3_低電圧基本動作!G11 | D15: =IF(ISNUMBER(C15),C15-2.68,"") | F15: v2.1.1 は 3.9V
A16: EN 電圧（Q6 ON 時） | B16: 78 mV | C16: =3_低電圧基本動作!G12 | D16: =IF(ISNUMBER(C16),C16-78,"")
A17: 待機電流 | B17: 460 µA | C17: =3_低電圧基本動作!G14 | D17: =IF(ISNUMBER(C17),C17-460,"") | F17: v2.1.1 は 60µA
A18: Vgs 終値 | B18: 12.0 V | C18: =4_起動波形!G7 | D18: =IF(ISNUMBER(C18),C18-12,"") | F18: 規格 10〜14V
A19: Vout 立ち上がり | B19: 57.2 ms（許容 42〜87） | C19: =4_起動波形!G8 | D19: =IF(ISNUMBER(C19),C19-57.2,"")
A20: 突入電流 | B20: 1.98 A（上限 2.4） | C20: =4_起動波形!G9 | D20: =IF(ISNUMBER(C20),C20-1.98,"")
A21: TIMER ピーク | B21: 2.0 V 未満 | C21: =4_起動波形!G10 | D21: — | F21: ラッチ電圧に対する余裕
A22: TP5 − TP2 間容量 | B22: 46.7 nF | C22: =4_起動波形!G11 | D22: =IF(ISNUMBER(C22),C22-46.7,"") | F22: 60nF 超なら C9 / C15 過大
A23: T_trip 遮断温度 | B23: 95 ℃（暫定） | C23: ='5_保護機能（マイコン）'!G6 | D23: =IF(ISNUMBER(C23),C23-95,"") | F23: 7-4 の実測で確定
A24: TH2 遮断温度 | B24: 110 ℃（暫定） | C24: ='5_保護機能（マイコン）'!G10 | D24: =IF(ISNUMBER(C24),C24-110,"") | F24: 7-11 の実測で確定
A25: 12V レール | B25: 12.0 V | C25: =8_ブレーキチョッパ!G5 | D25: =IF(ISNUMBER(C25),C25-12,"")
A26: 基準電圧 | B26: 2.495 V | C26: =8_ブレーキチョッパ!G6 | D26: =IF(ISNUMBER(C26),C26-2.495,"")
A27: チョッパ動作点 | B27: 32.2 V | C27: =8_ブレーキチョッパ!G11 | D27: =IF(ISNUMBER(C27),C27-32.2,"")
A28: チョッパ復帰点 | B28: 30.8 V | C28: =8_ブレーキチョッパ!G12 | D28: =IF(ISNUMBER(C28),C28-30.8,"")
A29: チョッパ電流 | B29: 0.161 A | C29: =8_ブレーキチョッパ!G15 | D29: =IF(ISNUMBER(C29),C29-0.161,"")
A31: 実測でのみ得られる値
A32: 項目 | B32: 実測値 | C32: 単位 | D32: この値で決まること
A33: MDDS30 入力容量 | B33: =4_起動波形!G5 | C33: µF | D33: C15 / C16 の実装可否（3628µF で実装済み）
A34: 筐体内周囲温度 | B34: =7_熱特性!G5 | C34: ℃ | D34: T_trip / T_hard の最終値
A35: ストール電流 | B35: =7_熱特性!G12 | C35: A | D35: R1（OCP しきい値）の妥当性
A36: R11 フランジ温度 | B36: =7_熱特性!G14 | C36: ℃ | D36: R11 の実装品質、熱抵抗 27.3K/W の裏取り
A37: TH2 の応答遅れ | B37: =7_熱特性!G17 | C37: 秒 | D37: ファームウェア #5 の判定遅延の妥当性
A38: バスリプル（18kHz） | B38: =9_走行時総合!G5 | C38: mV | D38: C5 のリプル耐性の余裕
A39: 制動時の最大 Vout | B39: =9_走行時総合!G11 | C39: V | D39: R11 の最終値（200Ω で足りるか）
A40: Vout 経路の電圧降下 | B40: =9_走行時総合!G12 | C40: mV | D40: 解析値（R70 0.5mΩ 挿入後に再解析が必要）の裏取り
A41: GND 経路の電圧降下 | B41: =9_走行時総合!G13 | C41: mV | D41: 解析値 0.975mΩ の裏取り
A42: チョッパ ON 積算の増分 | B42: =9_走行時総合!G16 | C42: — | D42: ファームウェア #6 の閾値
...

Sheet 変更履歴
A1: v2.1.1 からの変更履歴（v3.0.0）
A2: 試験時に設計値の根拠をたどるための記録。
A4: 試験仕様書の改訂内容
A5: 版 | B5: 対象 | C5: 変更内容 | D5: 理由・根拠
A6: v3.0.0 | B6: 試験仕様書の構成 | C6: シートを 10 枚から 12 枚に再編し、試験番号を全面的に振り直した。実施順序を「3.3V → マイコン → 低電圧基本動作 → 起動波形」に変更 | D6: EN がフェイルセーフ（マイコンが能動的に保持しないと切れる）になったため、マイコンが動くまで Vout が出ない。v2.1.1 の順序（低電圧基本動作が最初）では 1 項目も測れない
A7: v3.0.0 | B7: 9_ENしきい値選別 | C7: シートを削除 | D7: 遮断点が LM5060 の EN しきい値ばらつき（0.80〜2.00V）ではなくファームウェアの定数で決まるため、量産選別が不要になった。EN は 2.68V と 78mV の 2 値だけを取り、どちらも ENTHH / ENTHL から十分離れている
A8: v3.0.0 | B8: 1_3.3V電源（新規） | C8: IC4（LMR16006XDDCR）の 12 項目を追加 | D8: マイコン電源の新設。VBUS（Q3 の前）から取るため、Vout が出ない状態でも検証できる
A9: v3.0.0 | B9: 2_MCU書き込みと基本動作（新規） | C9: IC6（STM32C011F4P6）の 22 項目を追加。JP1 のブリングアップ手順を 2-4 / 2-5 / 2-6 に明記 | D9: 未書込みのチップは GPIO が Hi-Z のため R42 1MΩ が EN_GATE を +3V3 へ引き上げ、Q6 が ON になって EN が落ちる。JP1 をブリッジすると EN_GATE が GND に固定され、ファームウェア無しでも電源部を動かせる。★ 書き込み後は必ず開放に戻す
A10: v3.0.0 | B10: 5_保護機能（マイコン） | C10: 判定基準を EN 電圧から温度そのものへ変更。ファームウェア #3〜#13 の 16 項目に拡張 | D10: 遮断点がファームの定数で決まるため、精度は NTC の J ランク ±5% と抵抗の 1% だけで決まり ±2〜3℃。v2.1.1 の「温度は参考値」という制約が消えた
A11: v3.0.0 | B11: 6_Q3ゲート保護（新規） | C11: R51 / D12 の検証 6 項目を追加 | D11: …R51 100Ω が C9 ∥ C15（44nF）をゲートから切り離し、D12（SMAJ15A）が Q3 の Ciss 2.7nF（max 3.4nF）分だけをクランプする。クランプ電流は 4.5A から 0.58A に下がる（7.8 分の 1）
A12: v3.0.0 | B12: 4_起動波形（旧 2_起動波形） | C12: TP5 の意味が変わったことを明記。4-3（Vgs 終値）を独立項目に分離 | D12: R51 が IC3.GATE と Q3 ゲートの間に入ったため、TP5 は /Gate_HV_1（R51 の下流＝真の Q3 ゲート）になった。C9 / C15 は Net-(IC3-GATE) 側。TP5 − TP10 が真の Vgs で、v2.1.1 より測定点として適切
A13: v3.0.0 | B13: 7_熱特性（旧 3_熱特性） | C13: 銅箔の熱抵抗（Q1 26.1 / Q2 25.9 / Q3 23.9 / R11 27.3 K/W）と損失予測の表を追加。Q3 の温度を独立項目に分離。TH2 / IC6 / IC4 の温度を追加 | D13: 基板図の実形状から熱抵抗を数値解析し、判定基準を「記録のみ」から定量値に置き換えた。Q3 は全電流を単独で流すため Q1 / Q2 より条件が厳しい
A14: v3.0.0 | B14: 7_熱特性 | C14: R5 の決定表を削除 | D14: R5 / R6 / R9（EN 分圧）が削除されたため
A15: v3.0.0 | B15: 10_GND分離（旧 7_GND分離） | C15: テストポイントと島の対応表を追加。10-4 / 10-5 / 10-7 を追加 | D15: v3.0.0 では ADC の基準電位が一点接続に乗るため重要度が上がった。10-7（ストール中の ADC 読み）が分離の実効性を最終判定する
A16: v3.0.0 | B16: 9_走行時総合（旧 6_走行時総合） | C16: 9-8 / 9-9（Vout / GND 経路の電圧降下）と 9-10〜9-12（ADC 精度・チョッパ積算）を追加 | D16: 経路抵抗の解析値（Vout 1.024mΩ / GND 0.975mΩ）の裏取り。★ R70 追加後は Vout 側を再解析すること
... A22: v2.3 → v3.0.0 | B22: 基板バージョン | C22: 設計仕様書は v2.3 として作成したが、基板・試験仕様書は v3.0.0 とする | D22: マイコン保護化・3.3V 電源の新設・EN 方式の変更・R51 / D12 の追加と、v2.1.1 からの差分が大きいため
A24: 設計（ハードウェア）の変更内容
A25: 区分 | B25: 対象 | C25: 内容 | D25: 理由
A26: 追加 | B26: IC4 + 周辺 | C26: LMR16006XDDCR による VBUS → 3.3V 降圧（0.7MHz、ECO 28µA） | D26: マイコン電源。VBUS 側（Q3 の前）から取る
A27: 追加 | B27: IC6 + 周辺 | C27: STM32C011F4P6（TSSOP-20） | D27: 保護制御。ADC で TH1 / TH2 / VBUS / Vout / チョッパを監視
A28: 追加 | B28: Q6 / R42 / R48 / C20 / JP1 | C28: BSS138 による EN 引き下げ（フェイルセーフ） | D28: マイコン死亡時に約 93ms で自動遮断。JP1 はブリングアップ用の強制 OFF
A29: 追加 | B29: TH2 | C29: R11 近傍に 2 個目の NTC（R11 から 5mm 離す） | D29: PPTC 撤去後 R11 の過熱保護が無いため
A30: 追加 | B30: J5 / J6 | C30: 拡張端子（JST XA 6極）/ SWD パッド（1×5 THT） | D30: v2.4 以降の外部センサー対応と書き込み。★ 2026-10-14 以降に J7（電流センス出力・JST GH 3極 SMD）/ J8（VBUS_AUX 出力・JST VH 2極 垂直）/ F4（2A 63V ヒューズ）を追加
A31: 追加 | B31: R51 / D12 | C31: Q3 のゲート保護（100Ω 直列 ＋ SMAJ15A） | D31: 2026-10-08、出力短絡で Q3 のゲート酸化膜が破壊された
A32: 追加 | B32: R50 | C32: +3V3 → NRST の 10kΩ（条件付き） | D32: J6 が MCU から離れ MCU_NRST の配線が伸びる場合のみ
A33: 削除 | B33: R5 / R6 / R9 | C33: EN 分圧を構成していた抵抗 | D33: EN 分圧方式を廃止
A34: 移設 | B34: TH1 | C34: EN 分圧から MCU の ADC へ。配置は v2.1.1 のまま（Q1〜Q3 の各ドレインパッドから約 1mm） | D34: 遮断点をファームで決めるため
A35: 変更 | B35: D8 | C35: BZT52C3V9（3.9V ツェナー）→ PESD5V0S1UL（5V ESD） | D35: EN 絶対最大は 75V。役割がクランプから ESD 保護に変わる
A36: 変更 | B36: C34 | C36: 100nF → 1nF | D36: マイコンによる高速短絡検出（応答 2ms）のため。100nF では分圧の時定数が 9.1ms になり間に合わない
... A45: 追加 | B45: F4 / J8 / R54 / C36 / C69 / R73(DNP) | C45: VBUS_AUX（2A 63V ヒューズ経由、B2P-VH 垂直）/ EXT_GPIO の 100Ω 直列 / EXT_ADC1 のフィルタ | D45: 2026-10-14 以降に追加・変更。R73 を DNP にしたため EXT_ADC1 に I_SENSE は来ない
A47: v2.1.1 → v3.0.0 試験番号の対応
A48: v2.1.1 | B48: 項目 | C48: v3.0.0 | D48: 備考
A49: 0_通電前確認 0-1〜0-6 | B49: 目視・短絡・導通・ビア | C49: 0_通電前確認 0-1 / 0-3〜0-5 / 0-8 / 0-9 | D49: 0-2（JP1）/ 0-6 / 0-7（3.3V）を挿入したため番号がずれる
A50: 0-7 / 0-8 | B50: VREF バイアス経路 / 分圧ノードの分離 | C50: 0-18 / 0-19 | D50: 内容は同一
A51: 0-9 | B51: F3 の導通 | C51: 0-20 | D51: 同一
A52: 0-10 | B52: J4 のピン配置 | C52: 0-21 | D52: 繋がるネットが 3.3V 系ロジックに変わった
A53: 0-11 | B53: Q4 ゲートプルダウン | C53: 0-17 | D53: 同一
A54: 1_低電圧基本動作 1-1〜1-5 | B54: UVLO / OVP / 非常停止 | C54: 3_低電圧基本動作 3-1〜3-5 | D54: 同一
A55: 1-6 | B55: EN 電圧 | C55: 3-7 | D55: ★ 設計値が 3.9V → 2.68V に変更
A56: 1-7 | B56: LED1 点灯 | C56: 3-9 | D56: 同一
...
