Workbook

Sheet 表紙・凡例
B2: MizuniGoal Power Controller v2.2.1 試験記録シート
B3: 7S4P LiPo 2並列ホットスワップ電源基板／Q3 ゲート保護（R51 / D12）追加版
B5: 基板情報
B6: 基板 No. | C6: 3 号機（v2.2.1 初号基板。1 号機は 2026-10-08 に Q3 破壊、2 号機は v2.1.1 のまま保持）
B7: 実装日
B8: 実装方法 | C8: PCBA / 手実装
B9: 銅厚 | C9: 1oz
B10: 表面仕上げ | C10: ENIG
B11: 試験実施者
B12: 試験実施日
B14: 凡例
B15: 黄色セル | C15: 記入欄。ここだけ入力してください
B16: 灰色セル | C16: 自動計算。数式が入っているので編集しないでください
B17: 判定列 | C17: OK / NG / 未実施 をドロップダウンから選択
B19: 安全上の注意
B20: ・7S LiPo は短絡時に数百 A を供給します。フェーズ2 までは可変電源（電流制限付き）で確認し、パック接続はフェーズ3 以降にしてください。
B21: ・フェーズ3 の 25A ストール試験では消火器を手元に置き、目を離さないこと。初回は 15A 程度から段階的に上げてください。
B22: ・v2.1.1 ではチョッパが fail-off 構成（Q5 による PNP 反転段）になったため、v2.0.0 で行っていた「R10 を外してチョッパを無効化する」手順は不要です。
B23: ・R11 は 27Ω から 200Ω（TPAN0263F200RK9）に変更され、チョッパ動作時の消費は 38.4W から 5.2W になりました。
B24: ・R11 の実効熱抵抗は 18℃/W 前後（v2.1.1 実測）。200Ω の連続導通では周囲 65℃ で平衡 158℃ となり、最高使用温度 150℃ を超えます。試験時は 120℃ を上限に中止してください。
B25: ・フェーズ8 の LED 線短絡試験（8-7）は意図的な短絡です。必ず電流制限付き電源で実施してください。
B26: ・フェーズ1 以降は、1-8 の待機電流測定を除き、非常停止ボタンを解除（スイッチ ON）した状態で実施してください。J4 の接点は NC で、押下中は EN 経路が開いて Vout が出ません。
B27: ・【2026-10-08 追加】出力（Vout − GND）を短絡させないこと。1 号機はこれで Q3 のゲート酸化膜が破壊されました。電源の電流制限（4A）は無関係で、上流コンデンサの電荷が原因です。MDDS30 の端子付近でプローブを扱う作業は、必ず電源を落としてから行ってください。
B28: 必要機材
B29: 機材 | C29: 用途 | D29: 必須度
B30: オシロスコープ（2ch 以上） | C30: 起動波形、チョッパ動作、回生プロファイル、リプル観測 | D30: 必須
B31: プローブ 2 本＋グランドスプリング | C31: TP 隣接の GND を活かすため | D31: 必須
B32: デジタルマルチメータ | C32: 電圧・抵抗の静的確認 | D32: 必須
B33: 2ch 熱電対温度計（K型・細線プローブ2本） | C33: Q1 と TH1 の温度差 | D33: 必須
B34: サーマルカメラ | C34: R11 のフランジ温度、基板上の熱の広がり | D34: 必須
B35: LCR メータ（100Hz 測定が可能なもの） | C35: MDDS30 の入力容量測定。1kHz では大容量電解を測れません | D35: 必須
B36: 可変電源（0〜35V、3A 程度、電流制限付き） | C36: 低電圧での段階確認、短絡試験 | D36: 必須
B37: クランプメータ（30A 以上） | C37: ストール電流の実測 | D37: 必須
B38: ヒートガン／ドライヤー | C38: TH1 の加熱試験 | D38: 必須
B39: 温度計 | C39: 筐体内周囲温度の実測 | D39: 必須
B40: ルーペ（8〜10倍、LED付） | C40: 実装状態の確認 | D40: 必須
B41: 電子負荷または抵抗負荷 | C41: 段階的な負荷試験 | D41: あれば有用

Sheet 0_通電前確認
A1: 0_通電前確認
A2: 通電前に必ず実施。ここで異常があれば通電しないこと。0-7 〜 0-11 は v2.1.1 で追加した項目です。 ※ 0-12 / 0-13 は 2026-10-08 の Q3 破壊を受けて v2.2.1 で追加した R51 / D12 の実装確認です。
A4: No. | B4: 項目 | C4: 手順・条件 | D4: 測定点 | E4: 設計値・判定基準 | F4: 単位 | G4: 実測値 | H4: 判定 | I4: 備考
A5: 0-1 | B5: 目視確認 | C5: ルーペで全部品を確認 | D5: 基板全体 | E5: ブリッジ・未はんだ・欠品・向き違いが無いこと | F5: —
A6: 0-2 | B6: 短絡確認 | C6: DMM の抵抗レンジ | D6: J1 の +/− 間 | E6: 数百Ω以上。C5 / C7 の充電で表示が上昇し続けること（数Ωで止まる場合は短絡） | F6: Ω
A7: 0-3 | B7: 短絡確認 | C7: 同上 | D7: J2 の +/− 間 | E7: 同上 | F7: Ω
A8: 0-4 | B8: 短絡確認 | C8: 同上 | D8: J3 の +/− 間 | E8: 同上 | F8: Ω
A9: 0-5 | B9: 導通確認 | C9: DMM のダイオードレンジ | D9: TP10→TP4 | E9: Q3 ボディダイオード方向で導通（約 0.5V） | F9: V
A10: 0-6 | B10: ビア確認 | C10: 基板を透かして裏面を確認 | D10: Q1/Q2/Q3 裏面 | E10: はんだの染み出しが無いこと（テンティング成立） | F10: —
A11: 0-7 | B11: VREF バイアス経路 | C11: DMM の抵抗レンジ（無通電） | D11: TP8 − TP11 | E11: 6.8kΩ 前後（R20 が 12V レールと VREF の間にあること）。C13 / C17 の充電で表示が安定するまで数秒かかるので、安定後の値を読む | F11: kΩ
A12: 0-8 | B12: 分圧ノードの分離 | C12: 同上 | D12: TP15 − TP11 | E12: OL、または表示が上昇し続けること。6.8kΩ 前後で安定したら R20 の接続先が誤っている | F12: —
A13: 0-9 | B13: F3 の導通 | C13: 同上 | D13: J3 の + 端子 − J4 pin1 | E13: 1.6〜15Ω（PPTC の正常時抵抗）。C7 / C11 の充電の影響を受けるので、安定後の値を読む | F13: Ω
A14: 0-10 | B14: J4 のピン配置 | C14: 基板とコネクタを目視・導通確認 | D14: J4 | E14: pin1 Vout_after_PPTC / pin2 GND / pin3 EN_1 側 / pin4 EN_2 側 | F14: —
A15: 0-11 | B15: Q4 ゲートプルダウン | C15: DMM の抵抗レンジ（無通電） | D15: TP9 − TP12 | E15: 100kΩ 前後（R13 が実装されていること） | F15: kΩ
A16: 0-12 | B16: R51 の実装・値 | C16: DMM の抵抗レンジ（無通電） | D16: TP5 − IC3.10 | E16: 100Ω ±5%（C22775）。★ v2.2.1 で追加。欠けると D12 が C9 ∥ C15 の 44nF を直接受け、短絡時に自身が焼損する | F16: Ω
A17: 0-13 | B17: D12 の向きと健全性 | C17: DMM のダイオードレンジ（無通電） | D17: TP5 − TP10 | E17: TP5 を ＋ にして OL、逆向きで 0.6〜0.9V。★ 向きが逆だと Vgs 12V で順方向導通し、Q3 が一切 ON しない | F17: V
A19: ※ 0-7 / 0-8 は v2.0.0 で R20 の接続先を誤っていた箇所です。R20 の上端が 12V レールではなく分圧ノードに繋がっていたため、TL431 にバイアス電流が流れず VREF が立ちませんでした。通電前にこの 2 項目を確認すれば、同種の誤りを検出できます。
A20: ※ 0-11 は fail-off 構成の要です。R13 が未実装だと Q4 のゲートが浮き、意図しない導通が起こり得ます。
A21: ※ 抵抗レンジでの測定は、どの項目も「表示が安定してから読む」か「上昇し続けることを確認する」のどちらかです。0-2〜0-4 は上昇し続けることが正常、0-7 / 0-9 は安定後の値が判定対象、0-8 は上昇し続けるか OL が正常です。
A22: ※ 測定前に C5 / C7 を放電させてください。前の測定で充電が残っていると高い値が表示され、短絡を見逃します。

Sheet 1_低電圧基本動作
A1: 1_低電圧基本動作
A2: 可変電源を電流制限 0.5A に設定し、J1 に接続して実施。パックはまだ接続しない。1-8 を除き、非常停止ボタンは解除（スイッチ ON）の状態で行うこと。
A4: No. | B4: 項目 | C4: 手順・条件 | D4: 測定点 | E4: 設計値・判定基準 | F4: 単位 | G4: 実測値 | H4: 判定 | I4: 備考
A5: 1-1 | B5: UVLO 遮断→復帰 | C5: 電源電圧を 0V から徐々に上げる（非常停止は解除状態） | D5: TP10 / TP19 | E5: 19.5V 付近で Q3 が ON | F5: V
A6: 1-2 | B6: UVLO ヒステリシス | C6: 電圧を徐々に下げる（同上） | D6: TP10 / TP19 | E6: 17.4V 付近で OFF | F6: V
A7: 1-3 | B7: OVP 遮断 | C7: 電圧を 35V まで上げる（同上） | D7: TP10 / TP19 | E7: 34.0V 付近で OFF | F7: V
A8: 1-4 | B8: OVP 復帰 | C8: 電圧を下げる（同上） | D8: TP10 / TP19 | E8: 30.1V 付近で復帰 | F8: V
A9: 1-5 | B9: 非常停止スイッチ | C9: ボタンを押す／ひねって解除 | D9: TP10 / TP19 | E9: 押すと OFF、解除で ON（NC 接点） | F9: —
A10: 1-6 | B10: EN 電圧 | C10: 25℃、バス 29.4V（非常停止は解除状態） | D10: TP7 / TP2 | E10: 3.9V（D8 でクランプ） | F10: V
A11: 1-7 | B11: LED1 点灯 | C11: Q3 が ON の状態（同上） | D11: LED1（基板上） | E11: 点灯すること（NPGD が Low） | F11: —
A12: 1-8 | B12: 待機電流 | C12: 非常停止ボタンを押した状態、バス 29.4V | D12: 電源の電流表示 | E12: 約 60µA | F12: µA
A14: ※ 1-1〜1-4 が設計値と大きくずれる場合、R2 / R3 / R4 の実装と値を確認してください。
A15: ※ 1-8：外部 LED は Vout から駆動されるため、遮断時は消灯し待機電流に加算されません。
A16: ※ J4 の接点は NC（ノーマルクローズ）です。非常停止ボタンが押された状態では EN 経路が開いており、Vout は出ません。1-1〜1-7 は必ずボタンを解除してから実施してください。
A17: ※ J4 にスイッチを接続せずに試験する場合は、pin3 − pin4 間を短絡して接点 ON を模擬してください。開放のままでは Vout が立ち上がりません。

Sheet 2_起動波形
A1: 2_起動波形
A2: MDDS30 を接続して実施。入力容量は実測済み（3580µF / 100Hz）で、C15 と C16 は実装済み。★電源の電流制限は 3A 以上に設定すること（突入 2A）。不足すると UVLO リトライで階段状の波形になり、測定が無効になる。
A4: No. | B4: 項目 | C4: 手順・条件 | D4: 測定点 | E4: 設計値・判定基準 | F4: 単位 | G4: 実測値 | H4: 判定 | I4: 備考
A5: 2-1 | B5: MDDS30 入力容量 | C5: 電源を切った状態で VB+/VB− 間を 100Hz で測定 | D5: MDDS30 | E5: 参考値。v2.0.0 実測では 3580µF | F5: µF
A6: 2-2 | B6: ゲート立ち上がり | C6: スイッチ ON、Ch1=TP5(GND:TP18)。10×プローブ、レンジは VBUS＋15V 以上 | D6: TP5 / TP18 | E6: 終値 VBUS＋12V（10〜14V）。立ち上がりは 0.545V/ms。VBUS 19.5/24.0/29.4V で 35.8/44.0/53.9ms | F6: ms | G6: 75.4 | H6: OK | I6: 2026-10-08 再測定（電流制限 4A）: 終値 40.1V、Vout 28.3V → Vgs 11.8V（規格 10〜14V）。単調・階段なし。10-90% 75.4ms
A7: 2-3 | B7: Vout 立ち上がり | C7: 同時観測、Ch2=TP10(GND:TP19) | D7: TP10 / TP19 | E7: VBUS÷0.545V/ms。19.5V:35.8ms / 24.0V:44.0ms / 29.4V:53.9ms。ゲート電流の幅で ±40% | F7: ms | G7: 74 | H7: OK | I7: 2026-10-08 再測定: 終値 28.3V、ランプ 74ms（10-90% 61.3ms）、単調。傾き 382V/s → ゲート電流は規格下限側の約17〜19µA（typ 24µA）。許容 40〜83ms 内
A8: 2-4 | B8: 突入電流 | C8: ①2-3 の傾きから算出（推奨）②低電位側シャント ③電源の電流制限でブラケット。下の表を参照 | D8: 入力配線 | E8: 1.98A（1.4〜2.6A）。VBUS に依存しない | F8: A | G8: 1.39 | H8: OK | I8: 2026-10-08: 2-3 の傾き 382V/s から 3628µF × 382 = 1.39A（主測定）。2-2 のゲート傾き 354V/s からは 1.29A で 7% 一致（クロスチェック）。基準 2.4A 以下
A9: 2-5 | B9: TIMER 波形 | C9: 起動時の TIMER ピン電圧 | D9: TP6 / TP2 | E9: 2V に達する前に起動完了すること | F9: V | G9: 0.76 | H9: OK | I9: 2026-10-08 長時間軸で確認: 1本目 ピーク0.70V(14.0mV/ms) → +24ms に 0.35V へリセット → 2本目 ピーク0.76V(15.0mV/ms) → +53ms に 0.00V へ放電し +99ms まで平坦。ラッチ 2.0V に対し余裕 2.6 倍
A11: C15 / C16 の実装判断（実測済み・記録用）
A12: MDDS30 入力容量 | B12: C15 | C12: C16 | D12: 立ち上がり | E12: TIMER 許容 | F12: 突入電流
A13: 2200µF 以下 | B13: 未実装 | C13: 未実装 | D13: 27.0ms | E13: 60ms | F13: —
A14: 3580µF（実測・採用） | B14: 22nF 実装 | C14: 0.15µF 実装 | D14: 53.9ms | E14: 87ms | F14: 2.0A
A15: ※ 2-3 で起動に失敗する場合、TIMER 満了が疑われます。C6 + C16 = 0.48µF の実装を確認してください。
A16: ※ 立ち上がり時間はゲート容量とゲート電流だけで決まり、負荷容量には依存しません。負荷容量が効くのは突入電流です。
A18: 2-4 突入電流の測定方法（クランプメータを使わない場合）
A19: 方法 | B19: 手順 | C19: 算出・判定 | D19: 長所 | E19: 短所
A20: ① 傾きから算出 （推奨） | B20: 2-3 の Vout 波形から立ち上がり時間を読む | C20: I = 3628µF × VBUS ÷ t_rise → 1.98A（許容 1.4〜2.6A） | D20: 追加部品なし。2-3 と同時に完了する | E20: MDDS30 自身の消費電流（数十mA）は含まれない
A21: ② 低電位側シャント | B21: MDDS30 の VB− と基板 GND の間に 0.22Ω/2W を挿入。オシロ GND は基板 GND、先端をシャントの MDDS30 側へ。1× プローブ、100mV/div | C21: 2A で 440mV。I = V_Rs ÷ 0.22 | D21: オシロの GND が基板 GND のままなので TP5 / TP10 と同時観測できる | E21: モータを外して実施し、試験後は必ず撤去すること（走行電流で焼損）。MDDS30 の制御系 GND が別経路で基板 GND に繋がっているとシャントが短絡される
A22: ③ 電源の電流制限 | B22: 電流制限を 2.5A に設定して起動。CC に入らなければ 2.5A 未満。上下から挟み込む | C22: CC に入った制限値がピークの上限 | D22: 部品不要 | E22: 電源の出力コンデンサが突入の一部を供給するため、実際より小さく出る。裏取り用
A24: ※ 突入電流はゲートのスルーレートで決まるため VBUS に依存しません。I = C_total × dV/dt = 3628µF × 0.545V/ms = 1.98A。VBUS が高いほど時間が延びるだけです。C_total = MDDS30 3580µF ＋ C7 47µF ＋ C11 1µF。
A25: ※ シャントを足しても突入電流は変わりません。電流を決めているのはゲートのスルーレートであってループ抵抗ではないためです。50ms の事象なので無誘導型である必要もありません。
A26: ※ 正常な波形はほぼ矩形です。約 2A が t_rise の間続き、Vout が VBUS に達した瞬間に MDDS30 の待機電流まで落ちます。先頭に鋭いスパイクが出た場合は C9 / C15（ゲートのスルーレート用 44nF、GATE−GND 間）の未実装またははんだ不良を疑ってください。
A27: ※ TP5 は GND 基準で VBUS より上に出ます。プローブは 10×、レンジは VBUS＋15V 以上を確保してください。
A28: ※ ゲート波形は 3 段階になります。(1) 0→約3V で Q3 がオン開始 (2) ミラー期間：Vgs が 3〜4V で平らなまま、GND 基準の TP5 は Vout と一緒に上昇（ここが t_rise）(3) Vout が VBUS に達した後、さらに 12V 分だけ上がって VBUS＋12V で停止（約22ms）。データシートの GATE−OUT 16.8V はツェナークランプの保護値で、正常動作では到達しません。
A29: ※ 2-3 の「TIMER 許容 87ms」は要確認です。C6＋C16 = 0.48µF を 6µA でラッチ電圧 2.0V まで充電すると 160ms になります。2-5 で TP6 の傾きを実測して確定してください（6µA / 0.48µF なら 12.5mV/ms）。
A31: 2026-10-08 の測定で判明した事項（再測定が必要）
A32: ■ 症状：2-2 / 2-3 とも立ち上がりが約 200ms（設計 53.9ms）で、前半が高周波の振動を伴う階段状になった。2-5 の TIMER は約 35ms 周期でリセットを繰り返した。
A33: ■ 原因：安定化電源の電流制限が約 0.3A。根拠は 4 点。(1) 後半の直線部ですでに Vgs ≒ 11.4V と Q3 は完全オンで、Vout は VBUS に追従しているだけ。(2) 直線部の傾き 73.5V/s から I = 3628µF × 73.5 = 0.27A。(3) 波形が指数ではなく直線（30ms ごとの増分 2.3/2.25/2.15/2.1V）＝定電流源の特徴。(4) 階段が終わる電圧 18.0〜18.4V が 1-2 の UVLO 立ち下がり実測 17.95V と一致。
A34: ■ 機序：Q3 がオン → 電源が 0.3A で頭打ち → VBUS が Vout まで下がる → UVLO を割って LM5060 が遮断し TIMER もリセット → 負荷が切れて VBUS 復帰 → 再起動、の繰り返し。1 サイクルごとに負荷容量が充電され階段状に上昇。Vout が 18V を超えると VBUS が UVLO を割らなくなりハンチング終了、以降は電源の CC 0.27A による直線充電。
A35: ■ 基板側の異常は見つかっていない。ゲート終値 40.6V（Vgs 11.8V、規格 10〜14V）は正常。極端に弱い電源に対して UVLO リトライを繰り返し、ラッチオフせず最終的に正常起動した点はむしろ保護動作の確認になっている。
A36: ■ 対策：電源の電流制限を 3A 以上にして再測定する（29.4V × 2A = 59W が瞬間的に必要）。電源の定格が足りない場合は実バッテリパックで測定する。電流制限を上げても階段が残る場合は電源の CC→CV 復帰が遅い機種なので、パックで確認すること。
... A51: 試行間の放電手順（MDDS30 入力容量 3628µF）
A52: 方法 | B52: 時定数 | C52: 0.5V 以下までの時間 | D52: 備考
A53: DMM（DCV） | B53: 36,000 s | C53: 不可 | D53: 入力 10MΩ。放電器具としては使えない。オシロのプローブも同じ。DMM は放電の「確認」に使う
A54: DMM（電流レンジ） | B54: — | C54: 禁止 | D54: ほぼ短絡。1.45J が流れ込みヒューズが飛ぶ。ヒューズレスの 10A レンジでは内部損傷の恐れ
A55: 1kΩ / 2W 放電棒 | B55: 3.6 s | C55: 約 15 秒 | D55: 28mA / 0.8W。ワニ口付きリードに抵抗を 1 本
A56: 100Ω / 5W 放電棒 | B56: 0.36 s | C56: 約 1.5 秒 | D56: 283mA / 8.0W（瞬時）。全エネルギー 1.45J なのでセメント抵抗で余裕
A57: 1kΩ / 3W 常設ブリーダ | B57: 3.6 s | C57: 約 15 秒（自動） | D57: 推奨。電源を切るだけで放電される。試験中 28mA / 0.8W は突入 1.39A に対し無視できる
A59: ■ 手順：①電源 OFF ②J4 スイッチ OFF ③MDDS30 の VB+ / VB− に放電棒を 15 秒（100Ω なら 2 秒）当てる ④外して DMM の DCV で 0.5V 以下を確認 ⑤次の試行へ。
A60: ■ 常設ブリーダを使う場合、0_通電前確認 の抵抗測定（0-2〜0-4、0-7）には影響するので、その試験の前には外すこと。
...

Sheet 3_熱特性
A1: 3_熱特性
A2: 熱電対は Q1 のパッケージ表面と、TH1 直近の銅島（部品本体ではない）に貼る。R11 はサーマルカメラで測る。
A4: No. | B4: 項目 | C4: 手順・条件 | D4: 測定点 | E4: 設計値・判定基準 | F4: 単位 | G4: 実測値 | H4: 判定 | I4: 備考
A5: 3-1 | B5: 筐体内周囲温度 | C5: 実機を筐体に組み込み、走行後に測定 | D5: 筐体内 | E5: 記録のみ（R5 決定の根拠） | F5: ℃
A6: 3-2 | B6: 通常走行 Q1 温度 | C6: 8A 走行時、熱電対 Ch1 | D6: Q1 パッケージ | E6: 周囲＋16℃ 程度 | F6: ℃
A7: 3-3 | B7: 通常走行 TH1 温度 | C7: 同時測定、熱電対 Ch2 | D7: TH1 直近の銅島 | E7: 遮断点 100℃ に対し 25℃ 以上の余裕 | F7: ℃
A8: 3-4 | B8: ストール時 Q1 温度 | C8: 車輪を押さえて 25A、同時測定 | D8: Q1 パッケージ | E8: 記録のみ | F8: ℃
A9: 3-5 | B9: ストール時 TH1 温度 | C9: 同上 | D9: TH1 直近の銅島 | E9: 記録のみ | F9: ℃
A10: 3-6 | B10: ストール電流 | C10: 同上、クランプメータ | D10: 入力配線 | E10: 25A 前後 | F10: A
A11: 3-7 | B11: 遮断までの時間 | C11: 3-4 を継続し、Q3 が OFF するまで | D11: TP10 / TP19 | E11: 記録のみ | F11: 秒
A12: 3-8 | B12: R11 フランジ温度 | C12: チョッパ連続導通（32.2V で 5.2W）、サーマルカメラ。温度が止まるまで観測 | D12: R11 フランジ | E12: 周囲＋95℃ 以上（実効熱抵抗 18℃/W 前後・実測）。平衡するまで数分かかる。120℃ を超えたら中止 | F12: ℃
A13: 3-9 | B13: 同時の TH1 温度 | C13: 同上 | D13: TH1 直近の銅島 | E13: ほぼ周囲温度のまま（v2.0.0 実測で確認済み。TH1 は R11 の過熱を検出しない） | F13: ℃
A14: 3-10 | B14: C7 表面温度 | C14: 同上 | D14: C7 表面 | E14: 電解の寿命確認。周囲＋数℃ に留まること | F14: ℃
A16: 温度オフセット（自動計算）
A17: 項目 | B17: 計算式 | C17: 値 | D17: 設計想定 | E17: 判定
A18: Q1 − TH1（ストール時） | B18: 3-4 − 3-5 | C18: =IF(COUNT(G8,G9)=2,G8-G9,"") | D18: 29℃（1oz）
A19: R11 − TH1（チョッパ動作時） | B19: 3-8 − 3-9 | C19: =IF(COUNT(G12,G13)=2,G12-G13,"") | D19: 大きく開く（TH1 は R11 を検出しない）
A21: R5 の決定表
A22: 実測結果 | B22: R5 | C22: 遮断温度 | D22: 備考
A23: 周囲 45℃ 以下、通常走行で余裕十分 | B23: 19.6kΩ | C23: 約 90℃ | D23: 保護を強化
A24: 周囲 50〜65℃、通常走行で余裕あり | B24: 14.7kΩ（現状） | C24: 約 100℃ | D24: 変更不要
A25: 通常走行で TH1 が 75℃ 超 | B25: 11.3kΩ | C25: 約 110℃ | D25: 放熱・筐体も見直し
A26: オフセットが 40℃ 超 | B26: R5 を上げる | C26: 遮断点を下げる | D26: TH1 を FET に近づける検討も
A27: ※ v2.0.0 の実測では、R11 が 111.5℃ のとき基板中央は 34.1℃、周囲 29.9℃ でした。熱は R11 の周辺 15mm 程度に留まり、TH1 には届きません。既存のサーマル遮断は R11 の過熱をカバーしません。
A28: ※ 実効熱抵抗は当初 5.8℃/W（v2.0.0・14.1W・飽和前の値）と見積もっていましたが、v2.1.1 の実測（32.5V / 5.28W で 120℃ に達しても平衡せず）から 18℃/W 前後と判明しました。自然対流は温度差に対して非線形で、低電力域ほど単位電力あたりの熱抵抗が悪化します。
A29: ※ この熱抵抗では、R11 = 200Ω の連続導通時に周囲 65℃ で平衡 158℃ となり、最高使用温度 150℃ を超えます。「fail-on でも壊れない」という当初の設計目標は 200Ω では達成できていません。
A30: ※ ただし正常動作でチョッパが連続導通することはなく、回生は 1〜2.5 秒で終わります。連続導通が起きるのは Q5 または Q4 の短絡故障時のみです。R11 の最終値は 6-6 / 6-7 の回生プロファイル実測で決めます。
A31: ※ 3-8 はサーマルカメラの外殻温度です。フランジ温度はこれより高くなります。

Sheet 4_保護機能
A1: 4_保護機能
A2: 判定は温度ではなく EN 電圧で行う。遮断点の温度は個体の EN しきい値で決まるため、9_ENしきい値選別 で算出すること。
A4: No. | B4: 項目 | C4: 手順・条件 | D4: 測定点 | E4: 設計値・判定基準 | F4: 単位 | G4: 実測値 | H4: 判定 | I4: 備考
A5: 4-1 | B5: 遮断の確認 | C5: ヒートガンで TH1 を加熱 | D5: TP10 / TP19 | E5: Vout が落ちること | F5: —
A6: 4-2 | B6: 遮断時の EN 電圧 | C6: 落ちた瞬間の TP7 を記録 | D6: TP7 / TP2 | E6: 1.15〜1.50V（R5 = 3.0kΩ 前提） | F6: V
A7: 4-3 | B7: 自動復帰の確認 | C7: 加熱をやめて冷却する | D7: TP10 / TP19 | E7: Vout が戻ること | F7: —
A8: 4-4 | B8: 復帰時の EN 電圧 | C8: 戻った瞬間の TP7 を記録 | D8: TP7 / TP2 | E8: 4-2 ＋ 150〜300mV | F8: V
A9: 4-5 | B9: 遮断時の TH1 温度（参考） | C9: サーマルカメラまたは熱電対 | D9: TH1 本体 | E9: 参考記録のみ。判定には使わない | F9: ℃
A10: 4-6 | B10: 常時 ON 時の EN 電圧 | C10: 25℃、VBUS 29.4V | D10: TP7 / TP2 | E10: 3.2V 前後（D8 クランプ） | F10: V
A11: 4-7 | B11: ホットスワップ | C11: J2 にパックを追加接続 | D11: TP4 / TP17 | E11: アークの程度、電圧降下を記録 | F11: V
A12: 4-8 | B12: 逆流阻止 | C12: 一方のパックを外す | D12: TP10 / TP19 | E12: 他方から給電が継続すること | F12: —
A13: 4-9 | B13: OCP（任意） | C13: 意図的な過電流。危険なため慎重に | D13: TP10 / TP19 | E13: ラッチオフし、非常停止の押下＋解除で復帰 | F13: A
A15: ヒステリシス（自動計算）
A16: 項目 | B16: 計算式 | C16: 値 | D16: 期待値
A17: EN ヒステリシス | B17: 4-4 − 4-2 | C17: =IF(COUNT(G6,G8)=2,(G8-G6)*1000,"") | D17: 200mV 前後（ENHYS typ）
A19: ※ v2.0.0 / v2.1.0 では「遮断 100.2℃ / 復帰 68.9℃」を判定基準としていましたが、前提ごと誤りでした。LM5060 の EN は比較器ではなくロジック入力で、データシートの 0.80V（ENTHL）と 2.00V（ENTHH）は「確実に Low / High と認識される保証値」です。実際のしきい値はその間の 1 点で、ヒステリシスは 200mV typ しかありません。
A20: ※ つまり 100.2℃ と 68.9℃ は、遮断点と復帰点ではなく「個体ばらつきの両端」でした。v2.1.1 の実測では EN しきい値 1.3V、温度ヒステリシスは約 6℃ です。
A21: ※ サーマルカメラによる温度測定は放射率と熱勾配で大きく外れます（真値 82℃ に対し 120℃ と表示されました）。4-5 は参考記録に留めてください。
A22: ※ 4-9 は必須ではありません。実施する場合は電流制限付き電源で行い、パックは使わないでください。
A23: ※ 充電状態の異なるパックで 4-8 を実施してください。満充電と放電末期の組み合わせが最悪条件です。

Sheet 5_ブレーキチョッパ
A1: 5_ブレーキチョッパ
A2: v2.1.1 では Q5（MMBT3906）による反転段で fail-off 構成。R10 の取り外しは不要です。
A4: No. | B4: 項目 | C4: 手順・条件 | D4: 測定点 | E4: 設計値・判定基準 | F4: 単位 | G4: 実測値 | H4: 判定 | I4: 備考
A5: 5-1 | B5: 12V レール | C5: Vout 29.4V、DMM | D5: TP8 / TP3 | E5: 12V ±5%（11.4〜12.6V） | F5: V
A6: 5-2 | B6: 基準電圧 | C6: 同上 | D6: TP11 / TP3 | E6: 2.495V ±0.5% | F6: V
A7: 5-3 | B7: 分圧ノード | C7: 同上 | D7: TP15 / TP3 | E7: Vout × 0.0774（29.4V で 2.28V） | F7: V
A8: 5-4 | B8: Q5 コレクタ（OFF） | C8: チョッパ非動作時 | D8: TP23 / TP3 | E8: Vout × 0.0077（29.4V で 226mV）。R14 経由で Chopper_Sense の電位が分圧されて現れる | F8: V
A9: 5-5 | B9: Q4 ゲート（OFF） | C9: 同上 | D9: TP9 / TP12 | E9: Vout × 0.0070（29.4V で 206mV）。5-4 の値を R12 / R13 で分圧した値 | F9: V
A10: 5-6 | B10: Q4 ドレイン（OFF） | C10: 同上 | D10: TP21 / TP12 | E10: Vout と同電位 | F10: V
A11: 5-7 | B11: チョッパ動作点 | C11: 電源電圧を 30V から慎重に上げる | D11: TP10 / TP19 | E11: 32.2V でクランプ開始 | F11: V
A12: 5-8 | B12: チョッパ復帰点 | C12: 電圧を下げる | D12: TP10 / TP19 | E12: 30.8V で復帰 | F12: V
A13: 5-9 | B13: Q5 コレクタ（ON） | C13: チョッパ動作中 | D13: TP23 / TP3 | E13: 11.9V 付近 | F13: V
A14: 5-10 | B14: Q4 ゲート（ON） | C14: 同上 | D14: TP9 / TP12 | E14: 10.9V 付近 | F14: V
A15: 5-11 | B15: チョッパ電流 | C15: R11 両端電圧から算出、または電源の電流表示 | D15: R11 / TP21 | E15: 0.161A 前後（32.2V / 200Ω） | F15: A
A16: 5-12 | B16: R11 のフランジ温度 | C16: 5-7 の状態を数十秒継続 | D16: R11 フランジ | E16: 周囲＋20℃ 程度（数十秒時点）。連続導通では 150℃ を超えるため長時間続けないこと | F16: ℃
A18: ※ 5-7 は OVP 動作点 34.0V に近いため、電圧はゆっくり上げてください。確認できたら速やかに下げます。
A19: ※ v2.0.0 ではチョッパが fail-on 構成で、R20 の接続誤り（上端が 12V レールではなく分圧ノード）により VREF が立たず Q4 が常時オンになる不具合がありました。v2.1.0 で修正済みです。
A20: ※ v2.1.1 の fail-off 構成では、LM397 の故障・12V レール喪失・Q5 のオープン故障・R21 の断線のいずれでも Q4 はオフになります。ただし VREF の崩壊と Q5 / Q4 の短絡故障は fail-on のままです。
A21: ※ R11 の実効熱抵抗は 18℃/W 前後（v2.1.1 実測）。5.2W の連続導通では平衡温度が 120℃ を大きく超えます。5-7 / 5-12 は短時間で切り上げてください。
A22: ※ 5-4 / 5-5 は 0V ではありません。R14（1MΩ）がヒステリシス用に Chopper_Sense と Q5 のコレクタを繋いでいるため、チョッパ OFF でも Chopper_Sense の電位が R14 と R12+R13 で分圧されて現れます。Chopper_Sig = Vout × 0.0775 × 110k/(1000k+110k) = Vout × 0.0077。
A23: ※ この性質を使うと、TP23 の実測値から Vout を逆算できます（Vout ≒ TP23 ÷ 0.0077）。32.2V まで上げなくても、分圧回路と R14 の結線が設計どおりかを低電圧のまま検証できます。
A24: ※ Q5 がオフであることは、ベース（Chopper_SigBase）と エミッタ（TP8）の電位差がほぼゼロであることで確認できます。v2.1.1 の実測ではベース 12.05V / TP8 − TP23 間 11.7V でした。

Sheet 6_走行時総合
A1: 6_走行時総合
A2: 実走行状態での確認。6-6 / 6-7 は R11 の最終値を決める項目で、本シートの最優先事項です。
A4: No. | B4: 項目 | C4: 手順・条件 | D4: 測定点 | E4: 設計値・判定基準 | F4: 単位 | G4: 実測値 | H4: 判定 | I4: 備考
A5: 6-1 | B5: バス電圧リプル | C5: 走行中、AC カップリング | D5: TP4 / TP17 | E5: 18kHz 成分が 100mV 以下 | F5: mV
A6: 6-2 | B6: Q1 ゲート波形 | C6: 走行中、Q1 のゲートを観測 | D6: Q1 ゲート | E6: 25ms 周期のリフレッシュのみ。周期外の落ち込みが無いこと | F6: —
A7: 6-3 | B7: 順方向降下 | C7: 8A 走行時、ツイストペアで差動測定 | D7: TP13 − TP4 | E7: 17mV 前後 | F7: mV
A8: 6-4 | B8: 遮断時の Vout | C8: 走行中にスイッチ OFF | D8: TP10 / TP19 | E8: 負に振れないこと（C7 が支える） | F8: V
A9: 6-5 | B9: 給電パックの判別 | C9: 走行中 | D9: TP13 / TP14 | E9: 電圧の高い側から給電されること | F9: V
A10: 6-6 | B10: 回生プロファイル | C10: 制動時、Ch1=TP21(GND:TP12)、Ch2=TP10 | D10: TP21 / TP12 | E10: 導通時間とデューティを記録。R11 を上げられる余地があるかの判断材料 | F10: ms
A11: 6-7 | B11: 制動時の最大 Vout | C11: 同時観測 | D11: TP10 / TP19 | E11: 34.0V（OVP）に達しないこと。余裕があれば R11 を 330Ω / 470Ω に上げられる | F11: V
A13: ※ 6-1 が 100mV を大きく超える場合、C5 のリプル電流定格（18kHz で約 1.06A）に対する余裕を再検討してください。
A14: ※ 6-2 で周期外の落ち込みがあれば、リプルによる逆流誤検出が起きています。
A15: ※ 6-7 で OVP に達する場合は R11 を引ききれていません。150Ω または 100Ω への変更を検討してください。200Ω は制動時間 2.5 秒以上を前提にした値です。
A16: ※ 回生エネルギーは並進 4.5J + ロータ慣性 約 1.8J = 約 6.3J と見積もっています。ロータ慣性はデータシートに記載がなく推定値です。
A17: ※ R11 の候補と、周囲 65℃・熱抵抗 18℃/W での連続導通時の平衡温度：200Ω → 158℃ / 330Ω → 122℃ / 470Ω → 105℃ / 680Ω → 93℃。引ききるのに必要な制動時間は 200Ω で 2.5 秒、470Ω で 5.9 秒です。
A18: ※ 6-7 で OVP に達する場合は引ききれていません。その場合 R11 を上げる方向には進めず、150Ω / 100Ω への変更を検討することになります。熱と回生能力はトレードオフです。

Sheet 7_GND分離
A1: 7_GND分離
A2: C5 のマイナス端子での一点接続が機能しているかの検証。
A4: No. | B4: 項目 | C4: 手順・条件 | D4: 測定点 | E4: 設計値・判定基準 | F4: 単位 | G4: 実測値 | H4: 判定 | I4: 備考
A5: 7-1 | B5: 制御GND−大電流GND | C5: チョッパ動作中、差動測定 | D5: TP3 − TP12 | E5: 数十 mV 以内 | F5: mV
A6: 7-2 | B6: 同上（通常走行時） | C6: 8A 走行中 | D6: TP3 − TP12 | E6: 数 mV 以内 | F6: mV
A8: ※ 想定を超える場合、GND の引き回しを見直してください。次版での改善項目になります。

Sheet 8_外部スイッチ・LED
A1: 8_外部スイッチ・LED
A2: v2.1.1 で追加した非常停止スイッチ（LED 付き、5 ピン、1NO1NC）と F3（PPTC）の確認。
A4: No. | B4: 項目 | C4: 手順・条件 | D4: 測定点 | E4: 設計値・判定基準 | F4: 単位 | G4: 実測値 | H4: 判定 | I4: 備考
A5: 8-1 | B5: 非常停止の遮断 | C5: ボタンを押す | D5: TP10 / TP19 | E5: Vout が 0V になること | F5: V
A6: 8-2 | B6: 復帰 | C6: ひねって解除 | D6: TP10 / TP19 | E6: Vout が復帰すること | F6: V
A7: 8-3 | B7: 接点の導通抵抗 | C7: 無通電、スイッチ解除状態 | D7: J4 pin3 − pin4 | E7: 1Ω 以下 | F7: Ω
A8: 8-4 | B8: LED 電流（34V） | C8: Vout を 34V に設定し、J4 pin1 の電流を測定 | D8: J4 pin1 | E8: 40mA 以下が望ましい | F8: mA
A9: 8-5 | B9: LED 電流（19.5V） | C9: Vout を 19.5V に設定 | D9: J4 pin1 | E9: 記録のみ（電圧依存性の確認） | F9: mA
A10: 8-6 | B10: F3 の電圧降下 | C10: 8-4 と同時に測定 | D10: Vout − J4 pin1 | E10: LED 電流 × 1.6〜15Ω | F10: mV
A11: 8-7 | B11: LED 線短絡時のトリップ | C11: 電流制限付き電源で J4 pin1 − pin2 を短絡 | D11: J4 | E11: F3 がトリップすること。1 秒以内 | F11: 秒
A12: 8-8 | B12: F3 の復帰時間 | C12: 短絡を解除し、LED が再点灯するまで | D12: 外部 LED | E12: 記録のみ | F12: 秒
A14: ※ 8-4 が 40mA を超える場合、F3 を 1206L020/60NR（ホールド電流 200mA）に変更してください。筐体内 65℃ ではホールド電流が 25℃ 定格の 6 割程度まで下がります。
A15: ※ 8-7 は意図的な短絡試験です。必ず電流制限付き電源で実施し、パックは接続しないでください。
A16: ※ F3（1206L010/60NR）の諸元：ホールド 100mA / トリップ 250mA / Vmax 60V / 正常時抵抗 1.6〜15Ω / 動作温度 −40〜85℃。
A17: ※ 外部 LED は Vout から駆動されるため、非常停止・サーマル遮断・OVP・UVLO のいずれで遮断されても消灯します。スイッチ位置ではなく実際の出力を示します。

Sheet 9_ENしきい値選別
A1: 9_ENしきい値選別
A2: 加熱せずに EN しきい値を測る量産選別。この値で遮断点が決まる。R5 = 3.0kΩ を前提とした窓。
A4: No. | B4: 項目 | C4: 手順・条件 | D4: 測定点 | E4: 設計値・判定基準 | F4: 単位 | G4: 実測値 | H4: 判定 | I4: 備考
A5: 9-1 | B5: 立ち上がりしきい値 | C5: 注入電圧を上げ、Vout が立つ点 | D5: TP7 / TP2 | E5: 記録のみ | F5: V
A6: 9-2 | B6: 立ち下がりしきい値 | C6: 注入電圧を下げ、Vout が落ちる点 | D6: TP7 / TP2 | E6: 1.15〜1.50V なら合格 | F6: V
A7: 9-3 | B7: ヒステリシス（自動計算） | C7: 9-1 − 9-2 | D7: — | E7: 150〜300mV | F7: mV | G7: =IF(COUNT(G5,G6)=2,(G5-G6)*1000,"")
A9: 試験手順（加熱不要・1 枚あたり 30 秒程度）
A10: 1. J4 を開放する（非常停止スイッチを外すか、pin3 の配線を外す）。VBUS からの EN 分圧経路が切れる
A11: 2. J1 に VBUS 24V を印加する（電流制限 0.5A）
A12: 3. 可変電源を TP7（＋）と TP2（−）に接続する。電流制限 1mA、上限 3V
A13: 4. 注入電圧を 0V からゆっくり上げ、Vout（TP10）が立った電圧を 9-1 に記録する
A14: 5. ゆっくり下げ、Vout が落ちた電圧を 9-2 に記録する
A15: 6. 9-2 が 1.15〜1.50V なら合格。外れた基板は交換する
A17: 9-2 から算出される遮断点（自動計算） | E17: R5 の実装値 (Ω) | F17: 3000 | G17: R_top (Ω) | H17: =10000+F17
A18: 項目 | B18: VBUS 19.5V（放電末期） | C18: VBUS 29.4V（満充電） | D18: 判定の目安
A19: 分圧下側抵抗 R_b (Ω) | B19: =IF(ISNUMBER($G$6),$G$6/((19.5-$G$6)/$H$17-0.000006),"") | C19: =IF(ISNUMBER($G$6),$G$6/((29.4-$G$6)/$H$17-0.000006),"") | D19: —
A20: TH1 の抵抗 (Ω) | B20: =IF(ISNUMBER(B19),1/(1/B19-1/100000),"") | C20: =IF(ISNUMBER(C19),1/(1/C19-1/100000),"") | D20: —
A21: TH1 の遮断点 (℃) | B21: =IF(ISNUMBER(B20),1/(1/298.15+LN(B20/10000)/3944)-273.15,"") | C21: =IF(ISNUMBER(C20),1/(1/298.15+LN(C20/10000)/3944)-273.15,"") | D21: 85℃ 以上が望ましい
A22: Q1 の推定温度 (℃) | B22: =IF(ISNUMBER(B21),B21+29,"") | C22: =IF(ISNUMBER(C21),C21+29,"") | D22: 140℃ 以下（Tjmax 150℃）
A23: 筐体内 65℃ での余裕 (℃) | B23: =IF(ISNUMBER(B21),B21-65,"") | C23: =IF(ISNUMBER(C21),C21-65,"") | D23: 20℃ 以上が望ましい
A25: ※ 9-2 の測定値は J4 を開放して TP7 に電圧を注入するため、LM5060 単体の EN しきい値であり R5 の値に依存しません。R5 に依存するのは下の算出温度だけです。F17 に実装値を入れてください（量産は 3.0kΩ、v2.1.1 初期ロットは 14.7kΩ）。
A26: ※ この窓は「通常走行時の TH1 上昇が周囲＋20℃ 以下」「Q1 − TH1 オフセット 29℃」を仮定した暫定値です。3-3 と 3-4 / 3-5 の実測が出たら再計算してください。
A27: ※ LM5060 自身の温度ドリフトはデータシートに規定がありません。25℃ で測った値が筐体内 65℃ でどう動くかは不明で、この選別では保証できません。根本的には次版でマイコンの ADC に移すのが確実です。
A28: ※ D8 が 3.9V でクランプするので、注入電圧は 3V を超えないでください。
A29: ※ 手順 3 の電流制限は 1mA 程度にしてください。EN の ENBIAS は 6µA なので十分です。
A31: 遮断点の個体ばらつき一覧（EN しきい値 × VBUS。TH1 温度 ℃）
A32: EN しきい値 | B32: 意味 | C32: R5=14.7kΩ 19.5V | D32: R5=14.7kΩ 24.0V | E32: R5=14.7kΩ 29.4V | F32: R5=3.0kΩ 19.5V | G32: R5=3.0kΩ 24.0V | H32: R5=3.0kΩ 29.4V
A33: 0.80 V | B33: ENTHL・最も遅く遮断 | C33: 85.4 | D33: 92.7 | E33: 100 | F33: 108 | G33: 116.1 | H33: 124.4
A34: 1.15 V | B34: 選別窓の下限 | C34: 73.2 | D34: 80.2 | E34: 87.1 | F34: 94.3 | G34: 102.1 | H34: 109.9
A35: 1.30 V | B35: v2.1.1 実測値 | C35: 69.2 | D35: 76.1 | E35: 82.9 | F35: 89.8 | G35: 97.5 | H35: 105.1
A36: 1.50 V | B36: 選別窓の上限 | C36: 64.6 | D36: 71.4 | E36: 78.1 | F36: 84.7 | G36: 92.2 | H36: 99.7
A37: 2.00 V | B37: ENTHH・最も早く遮断 | C37: 55.5 | D37: 62.1 | E37: 68.7 | F37: 74.6 | G37: 81.9 | H37: 89.2
A39: Q1 の推定接合部温度（上表 ＋ 29℃。Tjmax 150℃）
A40: EN しきい値 | B40: 意味 | C40: R5=14.7kΩ 19.5V | D40: R5=14.7kΩ 24.0V | E40: R5=14.7kΩ 29.4V | F40: R5=3.0kΩ 19.5V | G40: R5=3.0kΩ 24.0V | H40: R5=3.0kΩ 29.4V
A41: 0.80 V | B41: ENTHL・最も遅く遮断 | C41: 114 | D41: 122 | E41: 129 | F41: 137 | G41: 145 | H41: 153
A42: 1.15 V | B42: 選別窓の下限 | C42: 102 | D42: 109 | E42: 116 | F42: 123 | G42: 131 | H42: 139
A43: 1.30 V | B43: v2.1.1 実測値 | C43: 98 | D43: 105 | E43: 112 | F43: 119 | G43: 126 | H43: 134
A44: 1.50 V | B44: 選別窓の上限 | C44: 94 | D44: 100 | E44: 107 | F44: 114 | G44: 121 | H44: 129
A45: 2.00 V | B45: ENTHH・最も早く遮断 | C45: 84 | D45: 91 | E45: 98 | F45: 104 | G45: 111 | H45: 118
A48: ※ 算出式：V_EN =（VBUS / R_top − 6µA）/（1 / R_top + 1 / R_b）。R_top = R9 10kΩ + R5、R_b = R6 100kΩ ∥ TH1。TH1 = NCP21XV103J03RA（10kΩ、B = 3944）。
...

Sheet 10_Q3ゲート保護
A1: 10_Q3 ゲート保護（R51 / D12）
A2: 2026-10-08 の Q3 破壊を受けて v2.2.1 で追加した R51（100Ω 直列）と D12（SMAJ15A、ゲート−ソース間クランプ）の検証。
A4: No. | B4: 項目 | C4: 手順・条件 | D4: 測定点 | E4: 設計値・判定基準 | F4: 単位 | G4: 実測値 | H4: 判定 | I4: 備考
A5: 10-1 | B5: R51 の実装・値 | C5: DMM の抵抗レンジ（無通電） | D5: TP5 − IC3.10 | E5: 100Ω ±5%（C22775）。0-12 と同じ項目。本フェーズの前提として再確認する | F5: Ω
A6: 10-2 | B6: D12 の向きと健全性 | C6: DMM のダイオードレンジ（無通電） | D6: TP5 − TP10 | E6: TP5 を ＋ にして OL、逆向きで 0.6〜0.9V。0-13 と同じ項目 | F6: V
A7: 10-3 | B7: 通常動作時の非導通 | C7: VBUS 29.4V で運転中。2-2 の Vgs 終値を確認 | D7: TP5 − TP10 | E7: Vgs 10〜14V（v2.1.1 実測 11.8V）< SMAJ15A の Vbr min 16.7V。D12 が通常動作で導通しないこと | F7: V
A8: 10-4 | B8: ゲート電流への影響 | C8: 2-2 / 2-3 の立ち上がりを R51 挿入前（v2.1.1 の 2 号機データ）と比較 | D8: TP5 / TP10 | E8: 有意差がないこと。傾き 0.545V/ms と 29.4V で 53.9ms が維持されること。τ = 100Ω × Ciss 4.23nF(max) = 0.42µs は 53.9ms に対し無視できる | F8: ms
A9: 10-5 | B9: 短絡時の Vgs クランプ（任意） | C9: ★ MDDS30 とパックを必ず外す。電流制限 0.5A の可変電源で VBUS 29.4V。Ch1 = TP5、Ch2 = TP10（GND:TP19）で Vout − GND を短絡 | D9: TP5 − TP10 | E9: Vgs が ±20V（Q3 の定格）を超えないこと。17V 付近でクランプするのが設計どおり | F9: V
A10: 10-6 | B10: 短絡後の健全性 | C10: 10-5 の後、Q3 の健全性を確認 | D10: TP5 / TP10 / TP4 | E10: TP5 − TP10 が非導通、TP10 − TP4 が Q3 のボディダイオード方向のみ導通（0-5 と同じ）。遮断後に Vout が復帰すること | F10: —
A12: ★ 10-5 は任意項目です。実施する場合は MDDS30 とパックを必ず外してください。基板側だけなら C7 47µF ＋ C11 1µF の放電で済みますが、パックを繋いだままだと数百 A が流れます。
A13: ※ R51 / D12 の役割：出力短絡で Vout が急落すると、C9 ∥ C15（44nF、GATE−GND 間）がゲートを 41V 付近に保持し、Vgs が定格 ±20V を超えてゲート酸化膜が貫通します。R51 が 44nF をゲートから切り離し、D12 が Q3 の Ciss 3.25nF typ（max 4.23nF）分だけをクランプします。クランプ電流は 4.7A から 0.68A に下がります。
A14: ※ 2026-10-08 の破壊機序は「ゲート酸化膜の貫通 → 制御喪失 → 熱暴走で D−S も短絡」です。最終状態は D−S 短絡ですが、一次故障はゲートです。TP5 − TP10 導通 / TP5 − TP2 非導通 / Q1・Q2 無傷、で確定しています。
A15: ※ Q1 / Q2 が同じ事故で無傷だったのは、LM74610 がゲート−ソース間を直接駆動しているためです。ゲート−GND 間に大容量を持つのは Q3 だけでした。LM5060（IC3）も健全で、ゲート出力が約 22µA のチャージポンプで電流制限されているためです。
A16: ※ D12 は Q3 の足元に配置する指示です。v2.2.1 では D12 のカソードが Q3 のゲートパッドから 1.60mm、クランプループ周長が約 11.5mm です。
A17: ※ ★ Q1〜Q3 を BSC028N06NS に変更してはいけません。v2.2.1 には v3.0.0 のファームウェア #13（2ms 遮断）が無いため、持続的な短絡では LM5060 の VDS 保護（74〜106ms）に頼ることになり、Q3 に 8.6J が入ります。Tc 60℃ での SOA 許容電流は CSD18540Q5B（RθJC 0.8K/W・Tj 175℃）が 5.0A、BSC028N06NS（RθJC 1.5K/W・Tj 150℃）が 2.1A で、後者は 4A に対して SOA を超えます。

Sheet サマリ
A1: 設計値と実測値の比較サマリ
A2: 各シートに入力すると自動で反映されます（灰色セル）。
A4: 項目 | B4: 設計値 | C4: 実測値 | D4: 差 | E4: 判定 | F4: 備考
A5: UVLO 遮断 | B5: 19.5 V | C5: =1_低電圧基本動作!G5 | D5: =IF(ISNUMBER(C5),C5-19.5,"")
A6: UVLO 復帰 | B6: 17.4 V | C6: =1_低電圧基本動作!G6 | D6: =IF(ISNUMBER(C6),C6-17.4,"")
A7: OVP 遮断 | B7: 34.0 V | C7: =1_低電圧基本動作!G7 | D7: =IF(ISNUMBER(C7),C7-34,"")
A8: OVP 復帰 | B8: 30.1 V | C8: =1_低電圧基本動作!G8 | D8: =IF(ISNUMBER(C8),C8-30.1,"")
A9: EN 電圧（25℃） | B9: 3.9 V | C9: =1_低電圧基本動作!G10 | D9: =IF(ISNUMBER(C9),C9-3.9,"")
A10: 立ち上がり時間 | B10: 53.9 ms | C10: =2_起動波形!G7 | D10: =IF(ISNUMBER(C10),C10-53.9,"")
A11: 突入電流 | B11: 2.0 A | C11: =2_起動波形!G8 | D11: =IF(ISNUMBER(C11),C11-2,"")
A12: EN 立ち下がりしきい値 | B12: 1.15〜1.50 V | C12: =9_ENしきい値選別!G6 | D12: —
A13: EN ヒステリシス | B13: 200 mV | C13: =9_ENしきい値選別!G7 | D13: =IF(ISNUMBER(C13),C13-200,"")
A14: 12V レール | B14: 12.0 V | C14: =5_ブレーキチョッパ!G5 | D14: =IF(ISNUMBER(C14),C14-12,"")
A15: 基準電圧 | B15: 2.495 V | C15: =5_ブレーキチョッパ!G6 | D15: =IF(ISNUMBER(C15),C15-2.495,"")
A16: チョッパ動作点 | B16: 32.2 V | C16: =5_ブレーキチョッパ!G11 | D16: =IF(ISNUMBER(C16),C16-32.2,"")
A17: チョッパ復帰点 | B17: 30.8 V | C17: =5_ブレーキチョッパ!G12 | D17: =IF(ISNUMBER(C17),C17-30.8,"")
A18: チョッパ電流 | B18: 0.161 A | C18: =5_ブレーキチョッパ!G15 | D18: =IF(ISNUMBER(C18),C18-0.161,"")
A19: Vgs 終値（クランプ余裕） | B19: 12.0 V | C19: =10_Q3ゲート保護!G7 | D19: =IF(ISNUMBER(C19),C19-12,"") | F19: D12 Vbr min 16.7V に対する余裕
A20: 実測でのみ得られる値
A21: 項目 | B21: 実測値 | C21: 単位 | D21: この値で決まること
A22: MDDS30 入力容量 | B22: =2_起動波形!G5 | C22: µF | D22: C15 / C16 の実装可否（3580µF で実装済み）
A23: 筐体内周囲温度 | B23: =3_熱特性!G5 | C23: ℃ | D23: R5 の最終値
A24: Q1 − TH1 オフセット | B24: =3_熱特性!C18 | C24: ℃ | D24: R5 の最終値、遮断点の妥当性
A25: ストール電流 | B25: =3_熱特性!G10 | C25: A | D25: R1（OCP しきい値）の妥当性
A26: R11 フランジ温度 | B26: =3_熱特性!G12 | C26: ℃ | D26: R11 の実装品質、熱抵抗の再確認
A27: バスリプル（18kHz） | B27: =6_走行時総合!G5 | C27: mV | D27: C5 のリプル耐性の余裕
A28: 制動時の最大 Vout | B28: =6_走行時総合!G11 | C28: V | D28: R11 の最終値（200Ω で足りるか）
A29: TP3−TP12 電位差 | B29: =7_GND分離!G5 | C29: mV | D29: GND 分離設計の妥当性
A30: LED 電流（34V） | B30: =8_外部スイッチ・LED!G8 | C30: mA | D30: F3 の品種（100mA 品で足りるか）
A31: サーマル遮断点（算出） | B31: =9_ENしきい値選別!B21 | C31: ℃ | D31: 放電末期での遮断点。65℃ 環境での余裕
A32: 総合判定
A33: 次版への申し送り事項

Sheet 変更履歴
A1: v2.0.0 からの変更履歴
A2: 試験時に設計値の根拠をたどるための記録。
A4: 版 | B4: 対象 | C4: 変更内容 | D4: 理由・根拠
A5: v2.1.0 | B5: R20 | C5: 上端の接続先を分圧ノードから 12V レール（Chopper_12V）へ修正 | D5: TL431 にバイアス電流が流れず VREF が立たなかった。動作点では分圧ノードと VREF が同電位になるため、原理的にカソード電流が得られない構成だった
A6: v2.1.0 | B6: U2 の入力 | C6: pin3(IN+) = VREF、pin1(IN−) = Chopper_Sense に入れ替え | D6: チョッパを fail-off 構成にするため。過電圧時に OUT が Low を引く向きにする
A7: v2.1.0 | B7: Q5 / R21 | C7: MMBT3906 による PNP 反転段を追加（R21 = 22kΩ） | D7: LM397 がオープンコレクタのため、能動的にオンさせないと Q4 が駆動されない構成にする
A8: v2.1.0 | B8: R19 | C8: Chopper_Sig のプルアップから Q5 のベース−エミッタ間プルアップへ役割変更 | D8: Q5 のオフ状態を保持するため。値は 10kΩ のまま
A9: v2.1.0 | B9: R14 | C9: 953kΩ → 1MΩ、接続先を U2 の OUT から Q5 のコレクタへ変更 | D9: 帰還ノードの振幅が 10.8V から 11.9V に変わったためヒステリシス幅を再計算。ΔVout = 1.40V
A10: v2.1.0 | B10: R11 | C10: 27Ω → 200Ω（RESI TPAN0263F200RK9） | D10: fail-on 時の消費を 38.4W から 5.2W に下げるため。当初は実効熱抵抗 5.8℃/W で周囲 65℃ でもフランジ 95℃ に収まる想定だったが、v2.1.1 の実測で 18℃/W 前後と判明し、連続導通時の平衡は 158℃ になる。最終値は 6-6 / 6-7 の回生プロファイル実測で決める
A11: v2.1.0 | B11: C17 | C11: U2 の電源に 1µF のデカップリングを追加 | D11: LM397 データシートの Layout Guidelines に従う
A12: v2.1.0 | B12: C15 / C16 | C12: 22nF / 0.15µF を実装（v2.0.0 は DNP） | D12: MDDS30 の入力容量を 100Hz で実測し 3580µF。未実装では突入電流が 4.0A となり基準 2.4A を超えるため
A13: v2.1.0 | B13: TP21 / TP23 | C13: Q4 ドレインと Q5 コレクタのテストポイントを追加 | D13: 回生プロファイルの測定と駆動段の健全性確認のため
A14: v2.1.0 | B14: TP3 / TP12 ほか | C14: GND テストポイントの一部をスルーホール化 | D14: ミノムシクリップで固定し、測定時に両手を空けるため
A15: v2.1.0 | B15: ポリスイッチ | C15: チョッパ経路への追加を検討したが不採用 | D15: R11 を 200Ω にしたことで fail-on 時の発熱が問題にならなくなったため。低バス電圧（19.5V / 0.72A）では 0.5A 品がトリップしないという制約もあった
... A27: v2.2.1 | B27: 試験仕様書 | C27: 0-12 / 0-13 と 10_Q3ゲート保護（10-1〜10-6）を追加 | D27: R51 / D12 の検証。Ciss 関連の数値は CSD18540Q5B 据え置きのため v2.1.1 から変更なし
