Workbook

Sheet 概要
A1: ローバー前後間ハーネス Ver.1：4極ハーネス（モーター用）＋14極ハーネス（信号用）の2本構成
A2: 正式な購入リスト（Ver.1、2026-10-21）。ハーネスは1本に束ねず、モーター用と信号用の2本に分ける
A3: 版数 | B3: Ver.1（2026-10-21）
A5: コネクタ | B5: Mini-Fit Jr. 4極（2×2）と14極（2×7）。各中継位置（③-②間、②-①間）に、4極ハーネス用と14極ハーネス用のコネクタをそれぞれ設ける
A6: ハーネス構成 | B6: 4極ハーネス：AV1.25 赤＋／黒−のツイストペア2組（左右モーター）／14極ハーネス：SX(NE) 0.5sq×7P 1本（RC・5V・CURR/VOLT・非常停止SW・LED）。2本は数cm離して配線し、交差は直角に
A7: ハウジング（モノタロウ、税込、10個入り） | B7: 5557-04R（08561481）307円＋5557-14R（08561533）659円＋5559-04P（08561296）395円＋5559-14P（08561341）736円
A8: ハウジング費用合計 | B8: 2,097円（20極コネクタ1個の構成と比べ約2,600円安い）
A9: 出荷 | B9: すべて当日出荷の表示
A10: ピン構成 | B10: 4極：モーター4本／14極：信号・電源14本（空きなし）
A11: 長所 | B11: 安価で納期が短い。モーター電力と信号がハーネスごと分離され、モーター線から信号線へのノイズ結合がさらに小さい（2本を数cm離せる）。浸水・ピン曲がり時の回り込みリスクも低い。4極だけ抜けばモーターだけを切り離せる（机上テストで安全）
A12: 短所・注意 | B12: 挿す箇所が2か所で挿し忘れの可能性（両端に「MOTOR」「SIGNAL」のラベルで対策）。ハーネスが2本になり、外装・クリップ・固定箇所が増える。パネル取付耳の有無は図面で確認
A13: 共通：端子 | B13: 5556T3L／5558T3L（AWG16、モーター線）、5556TL／5558TL（AWG18〜24、②ハーネスのSX(NE)）、5556T2L／5558T2L（AWG22〜28、①③ユニット側のAWG26）。すずめっき、各100個入り1パック
A14: 共通：ケーブル | B14: ②ハーネス：モーター＝エーモンAV1.25 赤・黒（自作ツイスト）／信号＝SX(NE) 0.5sq×7P（ペア1〜7、14芯すべて使用）。①③ユニット側（各約10cm）：モーター＝AWG16、5V・GND・CURRENT・VOLTAGE・RC・信号GND・ドレイン＝AWG26（住友電工 UL1571）、SW・LED＝AWG24（UL3265、150V）。PM02・Pixhawk側はJST GH 6ピンを自作
A15: 共通：性別 | B15: ③後部ユニット＝メス(5557)、②ハーネス後部側＝オス(5559)、②ハーネス前部側＝メス(5557)、①前部ユニット＝オス(5559)

Sheet ピン配置図

Sheet 購入リスト
A1: ハーネス部品 購入リスト Ver.1（Molex Mini-Fit Jr. 4極ハーネス＋14極ハーネス 2本構成）
A2: 「必要数」「購入数」は式で計算されます。「確認」「購入」列はプルダウンで選択、「実際に購入した品番」は手入力してください。
A4: No | B4: 区分 | C4: 部品名 | D4: メーカー | E4: 品番（例） | F4: 仕様 | G4: 必要数 | H4: 購入数 | I4: 単位 | J4: 確認ポイント | K4: 確認 | L4: 購入 | M4: 実際に購入した品番・備考 | N4: 品質文書（データシート・証明書）
A5: 1-1 | B5: コネクタ | C5: メス側ハウジング 4極（レセプタクル） | D5: 日本モレックス | E5: 5557-04R（モノタロウ 08561481） | F5: 4極、2×2、4.2mm、ナイロン66・UL94V-2、10個入り、税込307円 | G5: =条件!$B$5 -> 2 | H5: =ROUNDUP(G5/10,0) -> 1 | I5: パック | J5: モーター電力用。③後部ユニットと②ハーネスの前部側 | K5: 未確認 | L5: 未購入 | M5: 必要数は個数、購入数はパック数（1パック10個） | N5: https://www.molex.com/ja-jp/products/part-detail/39013042
A6: 1-2 | B6: コネクタ | C6: メス側ハウジング 14極（レセプタクル） | D6: 日本モレックス | E6: 5557-14R（モノタロウ 08561533） | F6: 14極、2×7、4.2mm、ナイロン66・UL94V-2、10個入り、税込659円 | G6: =条件!$B$5 -> 2 | H6: =ROUNDUP(G6/10,0) -> 1 | I6: パック | J6: 信号・電源用。③後部ユニットと②ハーネスの前部側 | K6: 未確認 | L6: 未購入 | M6: 必要数は個数、購入数はパック数（1パック10個） | N6: https://www.molex.com/ja-jp/products/part-detail/39012140
A7: 2-1 | B7: コネクタ | C7: オス側ハウジング 4極（プラグ） | D7: 日本モレックス | E7: 5559-04P（モノタロウ 08561296） | F7: 4極、2×2、4.2mm、ナイロン66・UL94V-2、10個入り、税込395円 | G7: =条件!$B$5 -> 2 | H7: =ROUNDUP(G7/10,0) -> 1 | I7: パック | J7: モーター電力用。②ハーネスの後部側と①前部ユニット。パネル取付耳の有無を図面で確認 | K7: 未確認 | L7: 未購入 | M7: 必要数は個数、購入数はパック数（1パック10個） | N7: https://www.molex.com/ja-jp/products/part-detail/39013043
A8: 2-2 | B8: コネクタ | C8: オス側ハウジング 14極（プラグ） | D8: 日本モレックス | E8: 5559-14P（モノタロウ 08561341） | F8: 14極、2×7、4.2mm、ナイロン66・UL94V-2、10個入り、税込736円 | G8: =条件!$B$5 -> 2 | H8: =ROUNDUP(G8/10,0) -> 1 | I8: パック | J8: 信号・電源用。②ハーネスの後部側と①前部ユニット。パネル取付耳の有無を図面で確認 | K8: 未確認 | L8: 未購入 | M8: 必要数は個数、購入数はパック数（1パック10個） | N8: https://www.molex.com/ja-jp/products/part-detail/39012141
A9: 3 | B9: 端子 | C9: メス端子 AWG16用 | D9: 日本モレックス | E9: 5556T3L（モノタロウ 75939272） | F9: メス端子 AWG16用、すずめっき2.5µm、バラ品、100個入り | G9: =条件!$B$5*条件!$B$6 -> 8 | H9: =ROUNDUP(G9*条件!$B$8/100,0) -> 1 | I9: パック | J9: すずめっきで統一。モーター線用 | K9: 未確認 | L9: 未購入 | M9: 必要数は個数、購入数はパック数（1パック100個） | N9: https://www.molex.com/ja-jp/products/part-detail/39000078
A10: 4 | B10: 端子 | C10: メス端子 AWG18〜24用 | D10: 日本モレックス | E10: 5556TL（モノタロウ 08561682） | F10: メス端子 AWG18〜24用、すずめっき2.5µm、バラ品、100個入り | G10: =条件!$B$5/2*条件!$B$7 -> 14 | H10: =ROUNDUP(G10*条件!$B$8/100,0) -> 1 | I10: パック | J10: すずめっきで統一。②ハーネス前部側（5557-14R）のSX(NE)芯線・ドレイン用。SX(NE)の絶縁体外径1.5mmは適合範囲1.3〜3.1mm内 | K10: 未確認 | L10: 未購入 | M10: 必要数は個数、購入数はパック数（1パック100個） | N10: https://www.molex.com/ja-jp/products/part-detail/39000038
A11: 4-2 | B11: 端子 | C11: メス端子 AWG22〜28用 | D11: 日本モレックス | E11: 5556T2L（モノタロウ 08561691） | F11: メス端子 AWG22〜28用（被覆外径0.90〜1.80mm）、すずめっき2.5µm、バラ品、100個入り、税込1,309円 | G11: =条件!$B$5/2*条件!$B$7 -> 14 | H11: =ROUNDUP(G11*条件!$B$8/100,0) -> 1 | I11: パック | J11: すずめっきで統一。③後部ユニット側（5557-14R）のAWG26（6線ケーブル・信号線）用 | K11: 未確認 | L11: 未購入 | M11: 必要数は個数、購入数はパック数（1パック100個） | N11: https://www.molex.com/ja-jp/products/part-detail/39000047
A12: 5 | B12: 端子 | C12: オス端子 AWG16用 | D12: 日本モレックス | E12: 5558T3L（モノタロウ 75939333） | F12: オス端子 AWG16用、すずめっき2.5µm、バラ品、100個入り | G12: =条件!$B$5*条件!$B$6 -> 8 | H12: =ROUNDUP(G12*条件!$B$8/100,0) -> 1 | I12: パック | J12: すずめっきで統一。モーター線用 | K12: 未確認 | L12: 未購入 | M12: 必要数は個数、購入数はパック数（1パック100個） | N12: https://www.molex.com/ja-jp/products/part-detail/39000125
A13: 6 | B13: 端子 | C13: オス端子 AWG18〜24用 | D13: 日本モレックス | E13: 5558TL（モノタロウ 08561454） | F13: オス端子 AWG18〜24用、すずめっき2.5µm、バラ品、100個入り | G13: =条件!$B$5/2*条件!$B$7 -> 14 | H13: =ROUNDUP(G13*条件!$B$8/100,0) -> 1 | I13: パック | J13: すずめっきで統一。②ハーネス後部側（5559-14P）のSX(NE)芯線・ドレイン用 | K13: 未確認 | L13: 未購入 | M13: 必要数は個数、購入数はパック数（1パック100個） | N13: https://www.molex.com/ja-jp/products/part-detail/39000121
A14: 6-2 | B14: 端子 | C14: オス端子 AWG22〜28用 | D14: 日本モレックス | E14: 5558T2L（モノタロウ 08561463） | F14: オス端子 AWG22〜28用（被覆外径0.90〜1.80mm）、すずめっき2.5µm、バラ品、100個入り、税込1,318円 | G14: =条件!$B$5/2*条件!$B$7 -> 14 | H14: =ROUNDUP(G14*条件!$B$8/100,0) -> 1 | I14: パック | J14: すずめっきで統一。①前部ユニット側（5559-14P）のAWG26（6線ケーブル・信号線）用 | K14: 未確認 | L14: 未購入 | M14: 必要数は個数、購入数はパック数（1パック100個） | N14: https://www.molex.com/ja-jp/products/part-detail/39000123
A15: 7 | B15: 工具 | C15: 圧着工具 16AWG用 | D15: IWISS（手持ち品で代用） | E15: SN-2549 ＋ 48Bダイス | F15: AWG16は48Bダイスの1.0〜1.5sqの溝で圧着 | G15: 0 | H15: =G15 -> 0 | I15: 本 | J15: 試し圧着で確認：被覆側バレルの閉じ具合（モーター線の被覆外径2.7mm）、Molex仕様書の圧着高さ、引っ張り試験、ハウジングへの挿入 | K15: 未確認 | L15: 未購入 | M15: 購入不要（手持ち品）。不良なら純正200218-2200または63811-1000を検討 | N15: なし（手持ち品）
A16: 8 | B16: 工具 | C16: 圧着工具 AWG20〜26用 | D16: IWISS（手持ち品で代用） | E16: SN-2549（標準ダイス） | F16: SX(NE) 0.5sq（AWG20相当、TL端子）とAWG26（T2L端子）をSN-2549の標準ダイスで圧着 | G16: 0 | H16: =G16 -> 0 | I16: 本 | J16: 試し圧着で確認：芯線・被覆の両バレルの巻き具合、引っ張り試験、ハウジングへの挿入。AWG26がダイスの適合範囲に入るか確認。被覆外径0.98mmはT2Lの下限（0.90mm）に近いので被覆バレルの保持を重点的に確認 | K16: 未確認 | L16: 未購入 | M16: 購入不要（手持ち品） | N16: なし（手持ち品）
A17: 9 | B17: 工具 | C17: 端子取り外し工具 | D17: Molex | E17: 11-03-0044 | F17: Mini-Fit Jr. 用エクストラクタ | G17: 1 | H17: =G17 -> 1 | I17: 本 | J17: ピン配置の修正、将来のDT移行に使用 | K17: 未確認 | L17: 未購入 | N17: https://www.molex.com/ja-jp/products/part-detail/11030044
A18: 10 | B18: 電線 | C18: 4極ハーネス用 モーター線 AV1.25 車両用ビニル線 赤・黒（自作ツイスト） | D18: エーモン（モノタロウ） | E18: 3470 AV1.25 6m（73991628）を赤・黒の2色で購入（黄・青は品切れ） | F18: 1.25sq、素線50本のより線、耐油・耐候性ビニル、導体最高許容温度80℃、許容電流11.6A。赤＝＋、黒＝−で左右モーター用に2組ツイスト | G18: 2 | H18: =G18 -> 2 | I18: 本（色） | J18: 被覆外径（約2.7〜3mm）を測り5556T3L／5558T3Lで試し圧着。各色約2.6m必要（6mで余裕あり）。左右は色で区別できないため、No.18のマーカーチューブで「R」「L」を表示 | K18: 未確認 | L18: 未購入 | M18: 赤・黒 各6m×1（作り直し・予備を含む）。将来の置き換え候補：大電 ロボトップ(DPC3-SB/2517)AWG16 4c（モノタロウ 34967274） | N18: なし（エーモン、購入先：モノタロウ 73991628）
A19: 11 | B19: コネクタ | C19: GH 6ピン ハウジング（PM02・Pixhawk側） | D19: 日本圧着端子製造（JST） | E19: GHR-06V-S | F19: 1.25mmピッチ、6極、ワイヤー対基板用ハウジング（JST GHシリーズ） | G19: 2 | H19: =G19 -> 2 | I19: 個 | J19: ③はPM02 V3の6ピン、①はPixhawk 6C Mini POWER1に挿す。ピン1・2＝5V、3＝CURRENT、4＝VOLTAGE、5・6＝GND（PM02付属ケーブルの並びと照合） | K19: 未確認 | L19: 未購入 | M19: 購入先未定。予備を含め多めに購入 | N19: JST GHシリーズ データシート：https://www.jst-mfg.com/product/pdf/eng/eGH.pdf
A20: 11-2 | B20: 端子 | C20: GH 圧着コンタクト | D20: 日本圧着端子製造（JST） | E20: SSHL-002T-P0.2 | F20: AWG30〜26（0.05〜0.13mm²）、被覆外径0.8〜1.0mm | G20: 12 | H20: =ROUNDUP(G20*条件!$B$8,0) -> 30 | I20: 個 | J20: 住友AWG26（被覆外径0.98mm）は適合範囲の上限付近。試し圧着で被覆バレルの閉じ具合とハウジングへの挿入を確認 | K20: 未確認 | L20: 未購入 | M20: 購入先未定。購入数は練習・予備分（条件シートの購入倍率）を含む | N20: JST GHシリーズ データシート：https://www.jst-mfg.com/product/pdf/eng/eGH.pdf
A21: 11-3 | B21: 工具 | C21: GH用 圧着工具 | D21: — | E21: 品番未定（JST GH SSHL-002T-P0.2に対応する1.25mmピッチ用ハンド圧着工具） | F21: AWG26〜30、オープンバレル端子用 | G21: 1 | H21: =G21 -> 1 | I21: 本 | J21: IWISS SN-2549（Mini-Fit用）では圧着できない。適合表でSSHL-002T-P0.2（AWG26）への対応を確認してから購入 | K21: 未確認 | L21: 未購入 | M21: 品番未定 | N21: 品番決定後に記入
A22: 12 | B22: 電線 | C22: ユニット側 AWG26 単線（5V×2・GND×2・CURRENT・VOLTAGE・RC右・RC左・信号GND・ドレイン） | D22: 住友電工（秋月電子） | E22: 耐熱電子ワイヤー 1m×9色 AWG26（秋月電子 118293） | F22: AWG26、7本／0.16mm すずめっき軟銅より線、被覆外径0.98mm、イラックスV2、最高80℃、税込440円 | G22: 1 | H22: =G22 -> 1 | I22: パック | J22: ①③とも約10cm×最大10本（6ピン電源用6本＋RC・信号GND・ドレイン4本）。UL AWM 1571（30V、80℃）。9色のため、足りない分はマーカーチューブで区別し、色の割り当てをピン配置シートに記録 | K22: 未確認 | L22: 未購入 | M22: 9色×1mで①③分に足りる | N22: UL AWM 1571 データシート（住友電工）：https://akizukidenshi.com/goodsaffix/ulawm1571.pdf
A23: 12-2 | B23: 電線 | C23: ユニット側 AWG24 単線（SW COM・SW NC・LED＋・LED−） | D23: 協和ハーモネット（秋月電子） | E23: 耐熱電子ワイヤー 2m×7色 UL3265 AWG24（秋月電子 106756） | F23: AWG24、11本／0.16mm すずめっき軟銅より線、被覆外径1.21mm、難燃架橋ポリエチレン、125℃、150V、税込720円 | G23: 1 | H23: =G23 -> 1 | I23: パック | J23: 7S LiPo電圧（最大29.4V）がかかる4本用。AWG26（UL1571）は定格30Vで余裕がないため、150V定格のこの線を使う。T2L端子（被覆外径0.90〜1.80mm）で圧着 | K23: 未確認 | L23: 未購入 | M23: ①③とも約10cm×4本 | N23: なし（協和ハーモネット、UL3265。購入先：秋月電子 106756）
A24: 13 | B24: 電線 | C24: 14極ハーネス用 シールド付きツイストペアケーブル（RC信号・5V・アナログ・非常停止SW・LED） | D24: 太陽ケーブルテック（旧テイコク） | E24: SX(NE) 0.5sq×7P（モノタロウ 5m巻 34956862） | F24: 0.5mm²×7対、編組シールド＋ドレインワイヤ、絶縁体外径1.5mm、仕上外径9.9mm、許容電流5.4A、150V | G24: 1 | H24: =G24 -> 1 | I24: 巻（5m） | J24: ペア1：RC右＋信号GND、ペア2：RC左＋信号GND、ペア3：5V＋GND、ペア4：SW COM＋NC、ペア5：LED＋＋LED−、ペア6：CURRENT＋VOLTAGE、ペア7：5V＋GND（2本目）。芯線の色をピン配置シートに記録。信号GNDは2本を1端子にダブル圧着 | K24: 未確認 | L24: 未購入 | M24: 5m巻×1（1台分の必要量は約1.2m。作り直し・予備を含む）。税別9,498円、出荷6日以内。2m巻（34956381）でも1台分は可 | N24: カタログ（IPROS）：https://mono.ipros.com/product/detail/2000637273/ SX(NE)仕様（MISUMI）：https://chk0-jp.misumi-ec.com/pdf/el/2015_H/1258.pdf 仕様変更のお知らせ：https://www.koshow.jp/topics/2023/07/post-18.html
A25: 14 | B25: 材料 | C25: 編組チューブ（PET編組スリーブ） | D25: デンカエレクトロン | E25: FL-12-5（モノタロウ 34658872、全長5m、最大径約24mm） | F25: ポリエステルモノフィラメント、−75〜125℃、UL224、自己消火性。自然折径幅約12〜13mm | G25: 1 | H25: =G25 -> 1 | I25: 本（5m） | J25: 2本のハーネスそれぞれに使用：4極ハーネス（AVツイストペア2組、外径10mm前後）、14極ハーネス（SX(NE)単体、外径9.9mm）。FL-12（自然折径約12mm、最大径約24mm）はどちらにも適合。切り口ははんだごてで溶着し、熱収縮チューブで仕上げる。SX(NE)はシースがあるため、擦れの心配がない区間は省略可 | K25: 未確認 | L25: 未購入 | M25: 5m巻×1から約0.72m×2本（4極用・14極用）を切り出す | N25: カタログ：https://jp.images-monotaro.com/etc/pdf/product/product_1462545_20251105_01.pdf RoHS2証明書：https://jp.images-monotaro.com/etc/pdf/product/product_1462545_20251105_02.pdf 非含有証明書：https://jp.images-monotaro.com/etc/pdf/product/product_1462545_20251105_03.pdf
A26: 15 | B26: 材料 | C26: 熱収縮チューブ（パック品） | D26: モノタロウ | E26: 収縮チューブ パック品（モノタロウ 60981052） | F26: 収縮前内径1.5/2.5/3.0/4.5/6.5/10.7/12.7mm 各1m×7本、2:1、−55〜125℃、600V | G26: 1 | H26: =G26 -> 1 | I26: セット | J26: 用途の目安：ドレイン線1.5mm、AV線ツイスト端10.7mm、SX(NE)外被端10.7〜12.7mm、編組チューブ端部（各ハーネス外径10mm前後）12.7mm | K26: 未確認 | L26: 未購入 | M26: PANDUIT HSTT-YK1／YK2は各15cm×2本で量が不足するため使用しない | N26: RoHS指令対応証明書：https://jp.images-monotaro.com/etc/pdf/rohs/G2773351_RoHS_done_20260703.pdf
A27: 16 | B27: 材料 | C27: ハーネス結束用テープ（布） | D27: モノタロウ | E27: テープ ハーネス結束用（モノタロウ 89826862） | F27: ポリエステル布基材、アクリル系粘着剤、幅19mm×19.6m、厚さ0.3mm、−40〜105℃、手切り可 | G27: 1 | H27: =G27 -> 1 | I27: 巻 | J27: 4極ハーネス（AVツイストペア2組）を10〜15cm間隔で束ねる。14極ハーネスはSX(NE)単体のため、端部とクリップ部の保護に使用。両端に巻いて「前部／後部」「MOTOR／SIGNAL」を油性ペンで記入 | K27: 未確認 | L27: 未購入 | M27: 今回はこちらを購入。代替：キタコ ハーネステープ PVC 0900-755-07010（モノタロウ 73778959、幅19mm×20m、税込395円） | N27: なし（モノタロウPB。SDS・RoHS等はモノタロウへ依頼可）
A28: 17 | B28: 材料 | C28: ケーブルクリップ（ねじ固定式） | D28: TRUSCO | E28: TCCシリーズ。同軸用：TCC0（適合径3.1mm、モノタロウ 48918886）。ハーネス用：4極・14極とも外径10mm前後のため12.7mmサイズが候補（ハーネスを組んで外径確認後に購入） | F28: ナイロン66、取付穴4.8mm（M4ねじ）、100個入り。適合径3.1〜36.7mmの12サイズ | G28: 1 | H28: =G28 -> 1 | I28: 袋 | J28: 4極ハーネス・14極ハーネス・GNSS同軸をそれぞれ別のクリップで固定し、互いに数cm離す。クリップはハーネスより少し大きいサイズを選び、隙間は布テープで調整。締めすぎ注意（ナイロン割れ・同軸の潰れ） | K28: 未確認 | L28: 未購入 | M28: TCC0×1袋を購入。ハーネス用（12.7mm候補）は外径確認後に追加購入。固定箇所はハーネス2本分（各3〜4か所）。M4ねじ・ナットは別途 | N28: なし（TRUSCO。SDS・RoHS等はモノタロウへ依頼可）
A29: 18 | B29: 材料 | C29: マーカーチューブ（ビニールチューブ 白） | D29: デンカエレクトロン | E29: TB-3.2W（モノタロウ 34690083） | F29: 内径3.2mm、肉厚0.45mm、軟質PVC、白、5m、−20〜60℃ | G29: 1 | H29: =G29 -> 1 | I29: 本（5m） | J29: 圧着前に電線へ通す。油性ペンで「R+」「R−」「L+」「L−」などと記入（必要に応じ透明熱収縮チューブで保護）。①②③の各端部に約1.5cm（最大24か所） | K29: 未確認 | L29: 未購入 | M29: AV線が赤黒2色のみのため左右の区別に使用。「前部」「後部」は布テープ（No.16）に記入 | N29: カタログ：https://jp.images-monotaro.com/etc/pdf/product/product_77055625_20250625_01.pdf RoHS2証明書：https://jp.images-monotaro.com/etc/pdf/product/product_77055625_20250625_02.pdf 含有有無：https://jp.images-monotaro.com/etc/pdf/product/product_77055625_20250625_03.pdf
A30: 19 | B30: コネクタ | C30: Dupont 1×3ピン ハウジング＋メス端子 | D30: — | E30: 2.54mmピッチ 1×3 ハウジング、メス圧着端子（AWG22〜28用） | F30: MDDS30のRC1・RC2（SIG・5V・GNDの3ピン）用。中央の5Vは空き | G30: 4 | H30: =G30 -> 4 | I30: 組 | J30: 前部：Pixhawk 6C Mini のRC出力（S・＋・−）用2組、後部：MDDS30 のRC1・RC2用2組。どちらも中央の＋（5V）は空き。ユニット側のAWG26をそのまま圧着。逆挿し防止のためハウジングと相手側にGND側の印、R／Lの印を付ける。振動で抜けないようホットボンド等で固定 | K30: 未確認 | L30: 未購入 | M30: ハウジング4個＋端子8個（予備含め多めに）。手持ちのDupontキットがあれば購入不要 | N30: なし（汎用品）
A31: 20 | B31: コネクタ | C31: XT60コネクタ（モーター接続用） | D31: Amass（常州アマス電子） | E31: XT60H-F（①ハーネス側＝通電側、メス）／XT60H-M（モーター側、オス） | F31: はんだカップ式、DC500V、定格30A（瞬間60A）、CE・UL | G31: 2 | H31: =G31 -> 2 | I31: 組 | J31: ①前部ユニットのモーター線（AWG16）と左右モーターの接続用。通電側（コントローラ側）をメスにする。モーターに既にXT60が付いている場合は性別を確認し、必要な側だけ購入。正規品は本体に「AMASS」の刻印があることを受入時に確認 | K31: 未確認 | L31: 未購入 | M31: 購入先候補：モノタロウ XT60H-M（68706666、税込208円、メーカー表記なし→刻印を確認）。メスは購入先未定 | N31: Amass XT60H-M 仕様シート：https://cdn.eicom.ru/media/PDF/XT60H-M.pdf Amass ダウンロードページ：https://www.china-amass.com/download/
A32: 21 | B32: コネクタ | C32: JST XA 4ピン ハウジング（電源基板のスイッチ用） | D32: 日本圧着端子製造（JST） | E32: XAP-04V-1 | F32: 2.5mmピッチ、4極、ワイヤー対基板用ハウジング | G32: 1 | H32: =G32 -> 1 | I32: 個 | J32: ③後部ユニットのSW COM・SW NC・LED＋・LED−を電源基板のスイッチ用コネクタへ。ピン並びは電源基板側の図面で確認 | K32: 未確認 | L32: 未購入 | M32: 購入先未定。予備を含め多めに購入 | N32: JST XA データシート：https://www.farnell.com/datasheets/1626572.pdf
A33: 21-2 | B33: 端子 | C33: JST XA 圧着コンタクト | D33: 日本圧着端子製造（JST） | E33: SXA-001T-P0.6 | F33: AWG28〜22（0.08〜0.33mm²） | G33: 4 | H33: =ROUNDUP(G33*条件!$B$8,0) -> 10 | I33: 個 | J33: SW・LED用のAWG24（UL3265）を圧着。適合する圧着工具（ダイス）を確認し、試し圧着で引っ張り試験 | K33: 未確認 | L33: 未購入 | M33: 購入先未定。購入数は練習・予備分（条件シートの購入倍率）を含む | N33: JST XA データシート：https://www.farnell.com/datasheets/1626572.pdf
A34: 22 | B34: 端子 | C34: 絶縁被覆付き丸形圧着端子（MDDS30のモーター出力用） | D34: ニチフ | E34: TMEV1.25-◯（◯＝ねじの呼び径。MDDS30の端子ねじに合わせる） | F34: 銅線用 R形（丸形）、1.25sq用、絶縁被覆ポリ塩化ビニル、JIS C 2805 | G34: 4 | H34: =G34 -> 4 | I34: 個 | J34: ③後部ユニットのモーター線（AV1.25）をMDDS30のMLA・MLB・MRA・MRBへ。MDDS30の端子台が「ねじで押さえ板を締める形」か「穴に差し込む形（ボックス形）」かを現物で確認。差し込む形の場合、丸形端子は使えないため棒形端子（フェルール）に変更する | K34: 未確認 | L34: 未購入 | M34: ねじ径とパック品の入数を確認して購入。JST FV1.25シリーズでも可 | N34: ニチフ TMEV カタログ：https://vn.c.misumi-ec.com/book/NCF1_E03/pdf/0001.pdf （代替）JST FV・Vシリーズ カタログ：https://docs.rs-online.com/941e/0900766b80fc8d98.pdf
A36: 集計
A37: 確認済の項目数 | C37: =COUNTIF(K5:K34,"確認済")&" / "&COUNTA(K5:K34) -> 0 / 30
A38: 受領済の項目数 | C38: =COUNTIF(L5:L34,"受領済")&" / "&COUNTA(L5:L34) -> 0 / 30
A40: 注記
A41: ・品番は公開されている販売店・メーカー資料で確認したもの（2026年10月時点）。購入前にMolexの製品ページで最新情報を確認してください。
A42: ・16AWG用端子の圧着工具・アプリケータは被覆外径別（1.80〜2.20mm、2.20〜2.45mm、2.60〜3.15mm）に分かれる。モーター線（エーモンAV1.25）の被覆外径は約2.7〜3mm。
A43: ・端子のめっきはオス・メスともすずめっきで統一する（すずと金を混ぜると、振動・水分によるフレッティング腐食や異種金属腐食で接触抵抗が上がる）。
...

Sheet ピン配置
A1: 4極ハーネス＋14極ハーネス 中継コネクタ ピン配置 Ver.1（両方の中継位置で共通）
A2: 実際のピン番号はハウジングの図面で確認し、「実際のピン番号」列に記入してください。
A4: コネクタ | B4: 列 | C4: 段 | D4: 信号 | E4: 電線 | F4: AWG | G4: 端子 | H4: 実際のピン番号 | I4: 備考
A5: 4極 | B5: 1 | C5: 上 | D5: 右M＋ | E5: エーモンAV1.25（赤） | F5: 1.25sq | G5: 16AWG用 | I5: 右モーターのツイストペア（赤＋／黒−）。両端にマーカー「R」
A6: 4極 | B6: 1 | C6: 下 | D6: 右M− | E6: エーモンAV1.25（黒） | F6: 1.25sq | G6: 16AWG用 | I6: 右モーターのツイストペアの相手線。マーカー「R」
A7: 4極 | B7: 2 | C7: 上 | D7: 左M＋ | E7: エーモンAV1.25（赤） | F7: 1.25sq | G7: 16AWG用 | I7: 左モーターのツイストペア（赤＋／黒−）。両端にマーカー「L」
A8: 4極 | B8: 2 | C8: 下 | D8: 左M− | E8: エーモンAV1.25（黒） | F8: 1.25sq | G8: 16AWG用 | I8: 左モーターのツイストペアの相手線。マーカー「L」
A9: 14極 | B9: 1 | C9: 上 | D9: 5V | E9: SX(NE) 0.5sq×7P | F9: 0.5sq | G9: 18〜24AWG用 | I9: ペア3。BEC（後部）からPixhawk等（前部）へ
A10: 14極 | B10: 1 | C10: 下 | D10: GND | E10: SX(NE) 0.5sq×7P | F10: 0.5sq | G10: 18〜24AWG用 | I10: ペア3の相手線。5V電流の戻り
A11: 14極 | B11: 2 | C11: 上 | D11: 5V（2本目） | E11: SX(NE) 0.5sq×7P | F11: 0.5sq | G11: 18〜24AWG用 | I11: ペア7。電圧降下を半減するため列4の5Vと両端で並列接続
A12: 14極 | B12: 2 | C12: 下 | D12: GND（2本目） | E12: SX(NE) 0.5sq×7P | F12: 0.5sq | G12: 18〜24AWG用 | I12: ペア7の相手線。列4のGNDと両端で並列接続
A13: 14極 | B13: 3 | C13: 上 | D13: CURRENT | E13: SX(NE) 0.5sq×7P | F13: 0.5sq | G13: 18〜24AWG用 | I13: ペア6。0〜3.3Vアナログ。25Vの線から離して配置
A14: 14極 | B14: 3 | C14: 下 | D14: VOLTAGE | E14: SX(NE) 0.5sq×7P | F14: 0.5sq | G14: 18〜24AWG用 | I14: ペア6の相手線。0〜3.3Vアナログ。基準は信号GND
A15: 14極 | B15: 4 | C15: 上 | D15: RC右 | E15: SX(NE) 0.5sq×7P | F15: 0.5sq | G15: 18〜24AWG用 | I15: ペア1
A16: 14極 | B16: 4 | C16: 下 | D16: RC左 | E16: SX(NE) 0.5sq×7P | F16: 0.5sq | G16: 18〜24AWG用 | I16: ペア2
... A22: 14極 | B22: 7 | C22: 下 | D22: LED− | E22: SX(NE) 0.5sq×7P | F22: 0.5sq | G22: 18〜24AWG用 | I22: ペア5の相手線。電源基板GNDへ専用線で戻す
A24: 配置ルール（4極・14極共通）：1列＝1組（ペア）、上段＝行き（＋・信号）、下段＝戻り（−・GND）。③・②・①の3か所すべてをこの配置で作る
A25: 性別（4極・14極とも）：③後部ユニット＝メス（5557）、②ハーネス後部側＝オス（5559）、②ハーネス前部側＝メス（5557）、①前部ユニット＝オス（5559）
A26: 4極ハーネス（モーター）と14極ハーネス（信号）は別々に配線し、数cm離す（交差は直角に）。両端に「MOTOR」「SIGNAL」のラベルを付け、挿し忘れを防ぐ（大きさが違うため差し違えは起きない）
A27: モーター電力と信号はハーネスごと分離されるため、20極構成の空き列（緩衝）は不要
A28: 5V・GNDは2本ずつ使い、①③の機器側（PM02／制御基板）でそれぞれ合流させる
A29: 色：オレンジ＝モーター電力、灰＝電源・GND、紫＝アナログ（0〜3.3V）、緑＝RC信号、ピンク＝7S LiPo電圧（電流制限あり）
A30: MDDS30側（③）：ユニット側のAWG26単線をそのままDupont 1×3（中央5Vは空き）に圧着。RC右→RC1のSIG、RC左→RC2のSIG。信号GNDの線とドレインの線はMDDS30の手前で1点に合流させ（はんだ付け＋熱収縮チューブ）、AWG26の2本に分岐してRC1・RC2のGNDへ。分岐後は各RCの信号線とGND線を軽くより合わせる
A32: SX(NE) 0.5sq×7P 芯線割り当て（7ペア・14本、すべて使用・予備なし）
A33: ペア | B33: 芯線の色（現物で記入） | D33: 芯線1の信号 | E33: 芯線1のピン（列・段） | G33: 芯線2の信号 | H33: 芯線2のピン | I33: 備考
A34: 1 | D34: RC右 | E34: 列4・上 | G34: 信号GND | H34: 列5・上 | I34: RC右の帰り線。ペア2の相手線と2本を1個の端子にダブル圧着。③側はユニットのAWG26線でドレインと合流後、RC1のGNDへ
A35: 2 | D35: RC左 | E35: 列4・下 | G35: 信号GND | H35: 列5・上 | I35: RC左の帰り線。ペア1の相手線とダブル圧着。③側はユニットのAWG26線でドレインと合流後、RC2のGNDへ
A36: 3 | D36: 5V | E36: 列1・上 | G36: GND | H36: 列1・下 | I36: 5V電流の行きと戻りを1ペアに
A37: 4 | D37: SW COM | E37: 列6・上 | G37: SW NC | H37: 列6・下 | I37: 非常停止スイッチ。7S LiPo電圧（直列抵抗で電流制限）
A38: 5 | D38: LED＋ | E38: 列7・上 | G38: LED− | H38: 列7・下 | I38: スイッチのLED。7S LiPo電圧（ポリスイッチで保護）
A39: 6 | D39: CURRENT | E39: 列3・上 | G39: VOLTAGE | H39: 列3・下 | I39: 0〜3.3Vアナログ。基準は信号GND（ペア1・2の相手線）
A40: 7 | D40: 5V（2本目） | E40: 列2・上 | G40: GND（2本目） | H40: 列2・下 | I40: ペア3と並列。両端の機器側で合流
A42: ドレイン線（裸線）：どの芯線ともつながず、単独で1個の端子に圧着して列5・下へ。外被を剥いだ所から端子の手前まで熱収縮チューブ（φ1.5mm程度）で絶縁する
A43: ドレインの接地はMDDS30側（③）のみ。②ハーネスでは両端ともドレイン線をドレインピンに圧着し、③ユニット側でAWG26線を出して信号GNDと合流させる。①ユニット側はドレインのキャビティを空けたまま（未接続）。シールド（編組）は両端で根元から切りそろえ、熱収縮チューブで覆う
A44: 14極コネクタの内訳：芯線14本で13ピン（信号GNDは2本で1ピン）＋ドレイン1ピン＝14ピン。空きピン・予備芯線はない
A45: 芯線の色はSX(NE)の現物で確認し、上の表の「芯線の色」列に記入してから圧着する
A47: ユニット側（①前部・③後部）の配線（コネクタから各機器まで、各約10cm）
A48: コネクタ | B48: 信号 | E48: 電線 | F48: 端子 | H48: 本数 | I48: 接続先・備考
A49: 4極 | B49: 右M＋・右M−・左M＋・左M− | E49: AWG16（エーモンAV1.25 赤・黒） | F49: 5556T3L／5558T3L | H49: 4 | I49: ③：MDDS30のモーター出力、①：左右モーター。赤＋／黒−をより合わせ、マーカーで「R」「L」
A50: 14極 | B50: 5V×2・GND×2・CURRENT・VOLTAGE | E50: AWG26単線（住友電工 UL1571） | F50: 5556T2L／5558T2L | H50: 6 | I50: ③：PM02 V3、①：Pixhawk 6C Mini POWER1。機器側はJST GH 6ピン（GHR-06V-S＋SSHL-002T-P0.2）を自分で圧着。GHの並び：1・2＝5V、3＝CURRENT、4＝VOLTAGE、5・6＝GND。前部5Vの見込み：1Aで約5.15V、3Aで約4.98V
...

Sheet 条件
A1: ハーネス部品 購入リスト：計算条件
A2: 黄色のセル（青字）が入力欄です。値を変えると「購入リスト」の数量が自動で再計算されます。
A4: 項目 | B4: 値 | C4: 単位 | D4: 根拠・備考
A5: 中継コネクタ位置の数（各サイズとも） | B5: 2 | C5: 組 | D5: ③-②間、②-①間の2か所。4極・14極それぞれ同数
A6: 1コネクタあたりのモーター用ピン数（AWG16） | B6: 4 | C6: 本 | D6: 右M＋、右M−、左M＋、左M−
A7: 14極コネクタ1個あたりのピン数 | B7: 14 | C7: 本 | D7: 5V×2、GND×2、CURRENT、VOLTAGE、RC右、RC左、信号GND、ドレイン、SW COM、SW NC、LED＋、LED−。②ハーネス側はTL端子（SX(NE)）、①③ユニット側はT2L端子（AWG26）
A8: 端子の購入倍率（練習・試験・予備分） | B8: 2.5 | C8: 倍 | D8: 圧着の練習と引っ張り試験用の余裕
A9: ②ハーネスの長さ | B9: 0.6 | C9: m | D9: ユーザー提示の50〜60cmの上限
A10: ①前部ユニットの引き出し長さ | B10: 0.1 | C10: m | D10: ユーザー提示の約10cm
A11: ③後部ユニットの引き出し長さ | B11: 0.1 | C11: m | D11: ユーザー提示の約10cm
A12: 電線の購入倍率（試作・作り直し分） | B12: 2 | C12: 倍 | D12: 作り直しに備えた余裕
A13: モーター線の本数 | B13: 4 | C13: 本 | D13: 左右×＋/−
A14: 編組スリーブの長さ倍率 | B14: 1.2 | C14: 倍 | D14: 端部処理・取り回し分
A15: ケーブルクランプの数 | B15: 6 | C15: 個 | D15: 仮定値。各コネクタの前後＋途中2か所
A17: 1区間あたりの電線長（①＋②＋③） | B17: =B9+B10+B11 -> 0.8 | C17: m
